Workbook
Name Print: Tue!$A$3:$P$52
Name SUBFRI: Fri!$A$71:$Z$107
Name SUBMON: Mon!$A$71:$Z$107
Name SUBSAT: Sat!$A$71:$Z$107
Name SUBTHUR: Thur!$A$71:$Z$107
Name SUBTUE: Tue!$A$71:$Z$107
Name SUBWED: Wed!$A$71:$Z$107

Sheet Mon
AC1: Monday
Y2: Hourly count of classes | AC2: V Semester | AG2: III Semester | AK2: I Semester
A3: TIME TABLE FOR THE YEAR 2020 - 2021 | I3: 43997 | P3: LEAVE | U3: Teachers | V3: Number of classes | X3: Teachers | Y3: 1st hour | Z3: 2nd hour | AA3: 3rd hour | AB3: 4th hour | AC3: 1st hour V sem | AD3: 2nd hour V sem | AE3: 3rd hour V sem | AF3: 4th hour V sem | AG3: 1st hour III Sem | AH3: 2nd hour III Sem | AI3: 3rd hour III Sem | AJ3: 4th hour III Sem | AK3: 1st hour I Sem | AL3: 2nd hour I Sem | AM3: 3rd hour I Sem | AN3: 4th hour I Sem | BX3: (SHA)red subjects dropdown
A4: Semester | C4: Section | E4: 8:30-9:20 | G4: 9:30-10:20 | I4: 10:20-10:50 | K4: 10:50-11:40 | M4: 11:50-12:40 | O4: Planned | P4: Planned | U4: (AB) | V4: =SUM(COUNTIF($E$5:$N$55,U4),IF(T4<>0,COUNTIF($E$5:$N$55,T4),0),IF(S4<>0,COUNTIF($E$5:$N$55,S4),0)) -> 2 | X4: =U4 -> (AB) | Y4: =SUM((COUNTIF($E$5:$F$55,$U4)),IF($T4<>0,(COUNTIF($E$5:$F$55,$T4))),IF($S4<>0,(COUNTIF($E$5:$F$55,$S4)))) -> 0 | Z4: =SUM(COUNTIF($G$5:$J$55,$U4),IF($T4<>0,(COUNTIF($G$5:$J$55,$T4))),IF($S4<>0,(COUNTIF($G$5:$J$55,$S4)))) -> 0 | AA4: =SUM(COUNTIF($K$5:$L$55,$U4),IF($T4<>0,(COUNTIF($K$5:$L$55,$T4))),IF($S4<>0,(COUNTIF($K$5:$L$55,$S4)))) -> 1 | AB4: =SUM(COUNTIF($M$5:$N$55,$U4),IF($T4<>0,(COUNTIF($M$5:$N$55,$T4))),IF($S4<>0,(COUNTIF($M$5:$N$55,$S4)))) -> 1 | AC4: =CONCATENATE(IF($U4=$F$5,$E$5,IF($U4=$F$6,$E$6,IF($U4=$F$7,$E$7,IF($U4=$F$8,$E$8,IF($U4=$F$9,$E$9,IF($U4=$F$10,$E$10,IF($U4=$F$11,$E$11,IF($U4=$F$12,$E$12,IF($U4=$F$13,$E$13,IF($U4=$F$14,$E$14,IF($U4=$F$15,$E$15,IF($U4=$F$16,$E$16,IF($U4=$F$17,$E$17,"")))))))))))))&" "&IF($U4=$F$5,"(A)",IF($U4=$F$6,"(B)",IF($U4=$F$7,"(C)",IF($U4=$F$8,"(D)",IF($U4=$F$9,"(E)",IF($U4=$F$10,"(F)",IF($U4=$F$11,"(G)",IF($U4=$F$12,"(H)",IF($U4=$F$13,"(I)",IF($U4=$F$14,"(J)",IF($U4=$F$15,"(K)",IF($U4=$F$16,"(L)",IF($U4=$F$17,"(L)","")))))))))))))) | AD4: =CONCATENATE(IF($U4=$H$5,$G$5,IF($U4=$H$6,$G$6,IF($U4=$H$7,$G$7,IF($U4=$H$8,$G$8,IF($U4=$H$9,$G$9,IF($U4=$H$10,$G$10,IF($U4=$H$11,$G$11,IF($U4=$H$12,$G$12,IF($U4=$H$13,$G$13,IF($U4=$H$14,$G$14,IF($U4=$H$15,$G$15,IF($U4=$H$16,$G$16,IF($U4=$H$17,$G$17,"")))))))))))))&" "&IF($U4=$H$5,"(A)",IF($U4=$H$6,"(B)",IF($U4=$H$7,"(C)",IF($U4=$H$8,"(D)",IF($U4=$H$9,"(E)",IF($U4=$H$10,"(F)",IF($U4=$H$11,"(G)",IF($U4=$H$12,"(H)",IF($U4=$H$13,"(I)",IF($U4=$H$14,"(J)",IF($U4=$H$15,"(K)",IF($U4=$H$16,"(L)",IF($U4=$H$17,"(L)","")))))))))))))) | AE4: =CONCATENATE(IF($U4=$L$5,$K$5,IF($U4=$L$6,$K$6,IF($U4=$L$7,$K$7,IF($U4=$L$8,$K$8,IF($U4=$L$9,$K$9,IF($U4=$L$10,$K$10,IF($U4=$L$11,$K$11,IF($U4=$L$12,$K$12,IF($U4=$L$13,$K$13,IF($U4=$L$14,$K$14,IF($U4=$L$15,$K$15,IF($U4=$L$16,$K$16,IF($U4=$L$17,$K$17,"")))))))))))))&" "&IF($U4=$L$5,"(A)",IF($U4=$L$6,"(B)",IF($U4=$L$7,"(C)",IF($U4=$L$8,"(D)",IF($U4=$L$9,"(E)",IF($U4=$L$10,"(F)",IF($U4=$L$11,"(G)",IF($U4=$L$12,"(H)",IF($U4=$L$13,"(I)",IF($U4=$L$14,"(J)",IF($U4=$L$15,"(K)",IF($U4=$L$16,"(L)",IF($U4=$L$17,"(L)","")))))))))))))) | AF4: =CONCATENATE(IF($U4=$N$5,$M$5,IF($U4=$N$6,$M$6,IF($U4=$N$7,$M$7,IF($U4=$N$8,$M$8,IF($U4=$N$9,$M$9,IF($U4=$N$10,$M$10,IF($U4=$N$11,$M$11,IF($U4=$N$12,$M$12,IF($U4=$N$13,$M$13,IF($U4=$N$14,$M$14,IF($U4=$N$15,$M$15,IF($U4=$N$16,$M$16,IF($U4=$N$17,$M$17,"")))))))))))))&" "&(IF($U4=$N$5,"(A)",IF($U4=$N$6,"(B)",IF($U4=$N$7,"(C)",IF($U4=$N$8,"(D)",IF($U4=$N$9,"(E)",IF($U4=$N$10,"(F)",IF($U4=$N$11,"(G)",IF($U4=$N$12,"(H)",IF($U4=$N$13,"(I)",IF($U4=$N$14,"(J)",IF($U4=$N$15,"(K)",IF($U4=$N$16,"(L)",IF($U4=$N$17,"(L)",""))))))))))))))) | AG4: =CONCATENATE(IF($U4=$F$21,$E$21,IF($U4=$F$22,$E$22,IF($U4=$F$23,$E$23,IF($U4=$F$24,$E$24,IF($U4=$F$25,$E$25,IF($U4=$F$26,$E$26,IF($U4=$F$27,$E$27,IF($U4=$F$28,$E$28,IF($U4=$F$29,$E$29,IF($U4=$F$30,$E$30,IF($U4=$F$31,$E$31,IF($U4=$F$32,$E$32,IF($U4=$F$33,$E$33,IF($U4=$F$34,$E$34,"")))))))))))))&" "&(IF($U4=$F$21,"(A)",IF($U4=$F$22,"(B)",IF($U4=$F$23,"(C)",IF($U4=$F$24,"(D)",IF($U4=$F$25,"(E)",IF($U4=$F$26,"(F)",IF($U4=$F$27,"(G)",IF($U4=$F$28,"(H)",IF($U4=$F$29,"(I)",IF($U4=$F$30,"(J)",IF($U4=$D$63,"(K)",IF($U4=$F$32,"(L)",IF($U4=$F$33,"(M)",IF($U4=$F$34,"(N)",""))))))))))))))))) | AH4: =CONCATENATE(IF($U4=$H$21,$G$21,IF($U4=$H$22,$G$22,IF($U4=$H$23,$G$23,IF($U4=$H$24,$G$24,IF($U4=$H$25,$G$25,IF($U4=$H$26,$G$26,IF($U4=$H$27,$G$27,IF($U4=$H$28,$G$28,IF($U4=$H$29,$G$29,IF($U4=$H$30,$G$30,IF($U4=$H$31,$G$31,IF($U4=$H$32,$G$32,IF($U4=$H$33,$G$33,IF($U4=$H$34,$G$34,""))))))))))))))&" "&(IF($U4=$H$21,"(A)",IF($U4=$H$22,"(B)",IF($U4=$H$23,"(C)",IF($U4=$H$24,"(D)",IF($U4=$H$25,"(E)",IF($U4=$H$26,"(F)",IF($U4=$H$27,"(G)",IF($U4=$H$28,"(H)",IF($U4=$H$29,"(I)",IF($U4=$H$30,"(J)",IF($U4=$H$31,"(K)",IF($U4=$H$32,"(L)",IF($U4=$H$33,"(M)",IF($U4=$H$34,"(N)","")))))))))))))))) | AI4: =CONCATENATE(IF($U4=$L$21,$K$21,IF($U4=$L$22,$K$22,IF($U4=$L$23,$K$23,IF($U4=$L$24,$K$24,IF($U4=$L$25,$K$25,IF($U4=$L$26,$K$26,IF($U4=$L$27,$K$27,IF($U4=$L$28,$K$28,IF($U4=$L$29,$K$29,IF($U4=$L$30,$K$30,IF($U4=$L$31,$K$31,IF($U4=$L$32,$K$32,IF($U4=$L$33,$K$33,IF($U4=$L$34,$K$34,""))))))))))))))&" "&IF($U4=$L$21,"(A)",IF($U4=$L$22,"(B)",IF($U4=$L$23,"(C)",IF($U4=$L$24,"(D)",IF($U4=$L$25,"(E)",IF($U4=$L$26,"(F)",IF($U4=$L$27,"(G)",IF($U4=$L$28,"(H)",IF($U4=$L$29,"(I)",IF($U4=$L$30,"(J)",IF($U4=$L$31,"(K)",IF($U4=$L$32,"(L)",IF($U4=$L$33,"(M)",IF($U4=$L$34,"(N)",""))))))))))))))) | AJ4: =CONCATENATE(IF($U4=$N$21,$M$21,IF($U4=$N$22,$M$22,IF($U4=$N$23,$M$23,IF($U4=$N$24,$M$24,IF($U4=$N$25,$M$25,IF($U4=$N$26,$M$26,IF($U4=$N$27,$M$27,IF($U4=$N$28,$M$28,IF($U4=$N$29,$M$29,IF($U4=$N$30,$M$30,IF($U4=$N$31,$M$31,IF($U4=$N$32,$M$32,IF($U4=$N$33,$M$33,IF($U4=$N$34,$M$34,""))))))))))))))&" "&(IF($U4=$N$21,"(A)",IF($U4=$N$22,"(B)",IF($U4=$N$23,"(C)",IF($U4=$N$24,"(D)",IF($U4=$N$25,"(E)",IF($U4=$N$26,"(F)",IF($U4=$N$27,"(G)",IF($U4=$N$28,"(H)",IF($U4=$N$29,"(I)",IF($U4=$N$30,"(J)",IF($U4=$N$31,"(K)",IF($U4=$N$32,"(L)",IF($U4=$N$33,"(M)",IF($U4=$N$34,"(N)","")))))))))))))))) | AK4: =CONCATENATE(IF($U4=$F$37,$E$37,IF($U4=$F$38,$E$38,IF($U4=$F$39,$E$39,IF($U4=$F$40,$E$40,IF($U4=$F$41,$E$41,IF($U4=$F$42,$E$42,IF($U4=$F$43,$E$43,IF($U4=$F$44,$E$44,IF($U4=$F$45,$E$45,IF($U4=$F$46,$E$46,IF($U4=$F$47,$E$47,IF($U4=$F$48,$E$48,IF($U4=$F$49,$E$49,IF($U4=$F$50,$E$50,IF($U4=$F$51,$E$51,""))))))))))))))&" "&IF($U4=$F$38,"(A)",IF($U4=$F$39,"(B)",IF($U4=$F$40,"(C)",IF($U4=$F$41,"(D)",IF($U4=$F$42,"(E)",IF($U4=$F$43,"(F)",IF($U4=$F$44,"(G)",IF($U4=$F$45,"(H)",IF($U4=$F$46,"(I)",IF($U4=$F$47,"(J)",IF($U4=$F$48,"(K)",IF($U4=$F$49,"(L)",IF($U4=$F$50,"(M)",IF($U4=$F$51,"(N)","")))))))))))))))) | AL4: =CONCATENATE(IF($U4=$H$37,$G$37,IF($U4=$H$38,$G$38,IF($U4=$H$39,$G$39,IF($U4=$H$40,$G$40,IF($U4=$H$41,$G$41,IF($U4=$H$42,$G$42,IF($U4=$H$43,$G$43,IF($U4=$H$44,$G$44,IF($U4=$H$45,$G$45,IF($U4=$H$46,$G$46,IF($U4=$H$47,$G$47,IF($U4=$H$48,$G$48,IF($U4=$H$49,$G$49,IF($U4=$H$50,$G$50,IF($U4=$H$51,$G$51,"")))))))))))))))&" "&IF($U4=$H$38,"(A)",IF($U4=$H$39,"(B)",IF($U4=$H$40,"(C)",IF($U4=$H$41,"(D)",IF($U4=$H$42,"(E)",IF($U4=$H$43,"(F)",IF($U4=$H$44,"(G)",IF($U4=$H$45,"(H)",IF($U4=$H$46,"(I)",IF($U4=$H$47,"(J)",IF($U4=$H$48,"(K)",IF($U4=$H$49,"(L)",IF($U4=$H$50,"(M)",IF($U4=$H$51,"(N)",""))))))))))))))) | AM4: =CONCATENATE(IF($U4=$L$37,$K$37,IF($U4=$L$38,$K$38,IF($U4=$L$39,$K$39,IF($U4=$L$40,$K$40,IF($U4=$L$41,$K$41,IF($U4=$L$42,$K$42,IF($U4=$L$43,$K$43,IF($U4=$L$44,$K$44,IF($U4=$L$45,$K$45,IF($U4=$L$46,$K$46,IF($U4=$L$47,$K$47,IF($U4=$L$48,$K$48,IF($U4=$L$49,$K$49,IF($U4=$L$50,$K$50,IF($U4=$L$51,$K$51,"")))))))))))))))&" "&IF($U4=$L$38,"(A)",IF($U4=$L$39,"(B)",IF($U4=$L$40,"(C)",IF($U4=$L$41,"(D)",IF($U4=$L$42,"(E)",IF($U4=$L$43,"(F)",IF($U4=$L$44,"(G)",IF($U4=$L$45,"(H)",IF($U4=$L$46,"(I)",IF($U4=$L$47,"(J)",IF($U4=$L$48,"(K)",IF($U4=$L$49,"(L)",IF($U4=$L$50,"(M)",IF($U4=$L$51,"(N)",""))))))))))))))) -> BT (J) | AN4: =CONCATENATE(IF($U4=$N$37,$M$37,IF($U4=$N$38,$M$38,IF($U4=$N$39,$M$39,IF($U4=$N$40,$M$40,IF($U4=$N$41,$M$41,IF($U4=$N$42,$M$42,IF($U4=$N$43,$M$43,IF($U4=$N$44,$M$44,IF($U4=$N$45,$M$45,IF($U4=$N$46,$M$46,IF($U4=$N$47,$M$47,IF($U4=$N$48,$M$48,IF($U4=$N$49,$M$49,IF($U4=$N$50,$M$50,IF($U4=$N$51,$M$51,"")))))))))))))))&" "&IF($U4=$N$38,"(A)",IF($U4=$N$39,"(B)",IF($U4=$N$40,"(C)",IF($U4=$N$41,"(D)",IF($U4=$N$42,"(E)",IF($U4=$N$43,"(F)",IF($U4=$N$44,"(G)",IF($U4=$N$45,"(H)",IF($U4=$N$46,"(I)",IF($U4=$N$47,"(J)",IF($U4=$N$48,"(K)",IF($U4=$N$49,"(L)",IF($U4=$N$50,"(M)",IF($U4=$N$51,"(N)",""))))))))))))))) -> BT (G) | BV4: Things to do | BX4: A, B, C | BY4: D | BZ4: E | CA4: F, G
A5: 5 | B5: F+ECOM | C5: A | E5: =_xlfn.XLOOKUP(F5, $A$100:$A$107, $B$100:$B$107, "Training") -> MA | F5: (KR) | G5: =_xlfn.XLOOKUP(H5, $A$100:$A$107, $B$100:$B$107, "Training") -> FMS | H5: (SUN) | I5: BREAK | K5: =_xlfn.XLOOKUP(L5, $A$100:$A$107, $B$100:$B$107, "Training") -> AA | L5: (SUP) | M5: =_xlfn.XLOOKUP(N5, $A$100:$A$107, $B$100:$B$107, "Training") -> IT | N5: (SRN) | O5: =IF(P5="",".",P5) -> . | U5: (AD) | V5: =SUM(COUNTIF($E$5:$N$55,U5),IF(T5<>0,COUNTIF($E$5:$N$55,T5),0),IF(S5<>0,COUNTIF($E$5:$N$55,S5),0)) -> 3 | X5: =U5 -> (AD) | Y5: =SUM((COUNTIF($E$5:$F$55,$U5)),IF($T5<>0,(COUNTIF($E$5:$F$55,$T5))),IF($S5<>0,(COUNTIF($E$5:$F$55,$S5)))) -> 1 | Z5: =SUM(COUNTIF($G$5:$J$55,$U5),IF($T5<>0,(COUNTIF($G$5:$J$55,$T5))),IF($S5<>0,(COUNTIF($G$5:$J$55,$S5)))) -> 1 | AA5: =SUM(COUNTIF($K$5:$L$55,$U5),IF($T5<>0,(COUNTIF($K$5:$L$55,$T5))),IF($S5<>0,(COUNTIF($K$5:$L$55,$S5)))) -> 0 | AB5: =SUM(COUNTIF($M$5:$N$55,$U5),IF($T5<>0,(COUNTIF($M$5:$N$55,$T5))),IF($S5<>0,(COUNTIF($M$5:$N$55,$S5)))) -> 1 | AC5: =CONCATENATE(IF($U5=$F$5,$E$5,IF($U5=$F$6,$E$6,IF($U5=$F$7,$E$7,IF($U5=$F$8,$E$8,IF($U5=$F$9,$E$9,IF($U5=$F$10,$E$10,IF($U5=$F$11,$E$11,IF($U5=$F$12,$E$12,IF($U5=$F$13,$E$13,IF($U5=$F$14,$E$14,IF($U5=$F$15,$E$15,IF($U5=$F$16,$E$16,IF($U5=$F$17,$E$17,"")))))))))))))&" "&IF($U5=$F$5,"(A)",IF($U5=$F$6,"(B)",IF($U5=$F$7,"(C)",IF($U5=$F$8,"(D)",IF($U5=$F$9,"(E)",IF($U5=$F$10,"(F)",IF($U5=$F$11,"(G)",IF($U5=$F$12,"(H)",IF($U5=$F$13,"(I)",IF($U5=$F$14,"(J)",IF($U5=$F$15,"(K)",IF($U5=$F$16,"(L)",IF($U5=$F$17,"(L)","")))))))))))))) -> IT (E) | AD5: =CONCATENATE(IF($U5=$H$5,$G$5,IF($U5=$H$6,$G$6,IF($U5=$H$7,$G$7,IF($U5=$H$8,$G$8,IF($U5=$H$9,$G$9,IF($U5=$H$10,$G$10,IF($U5=$H$11,$G$11,IF($U5=$H$12,$G$12,IF($U5=$H$13,$G$13,IF($U5=$H$14,$G$14,IF($U5=$H$15,$G$15,IF($U5=$H$16,$G$16,IF($U5=$H$17,$G$17,"")))))))))))))&" "&IF($U5=$H$5,"(A)",IF($U5=$H$6,"(B)",IF($U5=$H$7,"(C)",IF($U5=$H$8,"(D)",IF($U5=$H$9,"(E)",IF($U5=$H$10,"(F)",IF($U5=$H$11,"(G)",IF($U5=$H$12,"(H)",IF($U5=$H$13,"(I)",IF($U5=$H$14,"(J)",IF($U5=$H$15,"(K)",IF($U5=$H$16,"(L)",IF($U5=$H$17,"(L)","")))))))))))))) -> IT (K) | AE5: =CONCATENATE(IF($U5=$L$5,$K$5,IF($U5=$L$6,$K$6,IF($U5=$L$7,$K$7,IF($U5=$L$8,$K$8,IF($U5=$L$9,$K$9,IF($U5=$L$10,$K$10,IF($U5=$L$11,$K$11,IF($U5=$L$12,$K$12,IF($U5=$L$13,$K$13,IF($U5=$L$14,$K$14,IF($U5=$L$15,$K$15,IF($U5=$L$16,$K$16,IF($U5=$L$17,$K$17,"")))))))))))))&" "&IF($U5=$L$5,"(A)",IF($U5=$L$6,"(B)",IF($U5=$L$7,"(C)",IF($U5=$L$8,"(D)",IF($U5=$L$9,"(E)",IF($U5=$L$10,"(F)",IF($U5=$L$11,"(G)",IF($U5=$L$12,"(H)",IF($U5=$L$13,"(I)",IF($U5=$L$14,"(J)",IF($U5=$L$15,"(K)",IF($U5=$L$16,"(L)",IF($U5=$L$17,"(L)","")))))))))))))) | AF5: =CONCATENATE(IF($U5=$N$5,$M$5,IF($U5=$N$6,$M$6,IF($U5=$N$7,$M$7,IF($U5=$N$8,$M$8,IF($U5=$N$9,$M$9,IF($U5=$N$10,$M$10,IF($U5=$N$11,$M$11,IF($U5=$N$12,$M$12,IF($U5=$N$13,$M$13,IF($U5=$N$14,$M$14,IF($U5=$N$15,$M$15,IF($U5=$N$16,$M$16,IF($U5=$N$17,$M$17,"")))))))))))))&" "&(IF($U5=$N$5,"(A)",IF($U5=$N$6,"(B)",IF($U5=$N$7,"(C)",IF($U5=$N$8,"(D)",IF($U5=$N$9,"(E)",IF($U5=$N$10,"(F)",IF($U5=$N$11,"(G)",IF($U5=$N$12,"(H)",IF($U5=$N$13,"(I)",IF($U5=$N$14,"(J)",IF($U5=$N$15,"(K)",IF($U5=$N$16,"(L)",IF($U5=$N$17,"(L)",""))))))))))))))) -> RM (I) | AG5: =CONCATENATE(IF($U5=$F$21,$E$21,IF($U5=$F$22,$E$22,IF($U5=$F$23,$E$23,IF($U5=$F$24,$E$24,IF($U5=$F$25,$E$25,IF($U5=$F$26,$E$26,IF($U5=$F$27,$E$27,IF($U5=$F$28,$E$28,IF($U5=$F$29,$E$29,IF($U5=$F$30,$E$30,IF($U5=$F$31,$E$31,IF($U5=$F$32,$E$32,IF($U5=$F$33,$E$33,IF($U5=$F$34,$E$34,"")))))))))))))&" "&(IF($U5=$F$21,"(A)",IF($U5=$F$22,"(B)",IF($U5=$F$23,"(C)",IF($U5=$F$24,"(D)",IF($U5=$F$25,"(E)",IF($U5=$F$26,"(F)",IF($U5=$F$27,"(G)",IF($U5=$F$28,"(H)",IF($U5=$F$29,"(I)",IF($U5=$F$30,"(J)",IF($U5=$D$63,"(K)",IF($U5=$F$32,"(L)",IF($U5=$F$33,"(M)",IF($U5=$F$34,"(N)",""))))))))))))))))) | AH5: =CONCATENATE(IF($U5=$H$21,$G$21,IF($U5=$H$22,$G$22,IF($U5=$H$23,$G$23,IF($U5=$H$24,$G$24,IF($U5=$H$25,$G$25,IF($U5=$H$26,$G$26,IF($U5=$H$27,$G$27,IF($U5=$H$28,$G$28,IF($U5=$H$29,$G$29,IF($U5=$H$30,$G$30,IF($U5=$H$31,$G$31,IF($U5=$H$32,$G$32,IF($U5=$H$33,$G$33,IF($U5=$H$34,$G$34,""))))))))))))))&" "&(IF($U5=$H$21,"(A)",IF($U5=$H$22,"(B)",IF($U5=$H$23,"(C)",IF($U5=$H$24,"(D)",IF($U5=$H$25,"(E)",IF($U5=$H$26,"(F)",IF($U5=$H$27,"(G)",IF($U5=$H$28,"(H)",IF($U5=$H$29,"(I)",IF($U5=$H$30,"(J)",IF($U5=$H$31,"(K)",IF($U5=$H$32,"(L)",IF($U5=$H$33,"(M)",IF($U5=$H$34,"(N)","")))))))))))))))) | AI5: =CONCATENATE(IF($U5=$L$21,$K$21,IF($U5=$L$22,$K$22,IF($U5=$L$23,$K$23,IF($U5=$L$24,$K$24,IF($U5=$L$25,$K$25,IF($U5=$L$26,$K$26,IF($U5=$L$27,$K$27,IF($U5=$L$28,$K$28,IF($U5=$L$29,$K$29,IF($U5=$L$30,$K$30,IF($U5=$L$31,$K$31,IF($U5=$L$32,$K$32,IF($U5=$L$33,$K$33,IF($U5=$L$34,$K$34,""))))))))))))))&" "&IF($U5=$L$21,"(A)",IF($U5=$L$22,"(B)",IF($U5=$L$23,"(C)",IF($U5=$L$24,"(D)",IF($U5=$L$25,"(E)",IF($U5=$L$26,"(F)",IF($U5=$L$27,"(G)",IF($U5=$L$28,"(H)",IF($U5=$L$29,"(I)",IF($U5=$L$30,"(J)",IF($U5=$L$31,"(K)",IF($U5=$L$32,"(L)",IF($U5=$L$33,"(M)",IF($U5=$L$34,"(N)",""))))))))))))))) | AJ5: =CONCATENATE(IF($U5=$N$21,$M$21,IF($U5=$N$22,$M$22,IF($U5=$N$23,$M$23,IF($U5=$N$24,$M$24,IF($U5=$N$25,$M$25,IF($U5=$N$26,$M$26,IF($U5=$N$27,$M$27,IF($U5=$N$28,$M$28,IF($U5=$N$29,$M$29,IF($U5=$N$30,$M$30,IF($U5=$N$31,$M$31,IF($U5=$N$32,$M$32,IF($U5=$N$33,$M$33,IF($U5=$N$34,$M$34,""))))))))))))))&" "&(IF($U5=$N$21,"(A)",IF($U5=$N$22,"(B)",IF($U5=$N$23,"(C)",IF($U5=$N$24,"(D)",IF($U5=$N$25,"(E)",IF($U5=$N$26,"(F)",IF($U5=$N$27,"(G)",IF($U5=$N$28,"(H)",IF($U5=$N$29,"(I)",IF($U5=$N$30,"(J)",IF($U5=$N$31,"(K)",IF($U5=$N$32,"(L)",IF($U5=$N$33,"(M)",IF($U5=$N$34,"(N)","")))))))))))))))) | AK5: =CONCATENATE(IF($U5=$F$37,$E$37,IF($U5=$F$38,$E$38,IF($U5=$F$39,$E$39,IF($U5=$F$40,$E$40,IF($U5=$F$41,$E$41,IF($U5=$F$42,$E$42,IF($U5=$F$43,$E$43,IF($U5=$F$44,$E$44,IF($U5=$F$45,$E$45,IF($U5=$F$46,$E$46,IF($U5=$F$47,$E$47,IF($U5=$F$48,$E$48,IF($U5=$F$49,$E$49,IF($U5=$F$50,$E$50,IF($U5=$F$51,$E$51,""))))))))))))))&" "&IF($U5=$F$38,"(A)",IF($U5=$F$39,"(B)",IF($U5=$F$40,"(C)",IF($U5=$F$41,"(D)",IF($U5=$F$42,"(E)",IF($U5=$F$43,"(F)",IF($U5=$F$44,"(G)",IF($U5=$F$45,"(H)",IF($U5=$F$46,"(I)",IF($U5=$F$47,"(J)",IF($U5=$F$48,"(K)",IF($U5=$F$49,"(L)",IF($U5=$F$50,"(M)",IF($U5=$F$51,"(N)","")))))))))))))))) | AL5: =CONCATENATE(IF($U5=$H$37,$G$37,IF($U5=$H$38,$G$38,IF($U5=$H$39,$G$39,IF($U5=$H$40,$G$40,IF($U5=$H$41,$G$41,IF($U5=$H$42,$G$42,IF($U5=$H$43,$G$43,IF($U5=$H$44,$G$44,IF($U5=$H$45,$G$45,IF($U5=$H$46,$G$46,IF($U5=$H$47,$G$47,IF($U5=$H$48,$G$48,IF($U5=$H$49,$G$49,IF($U5=$H$50,$G$50,IF($U5=$H$51,$G$51,"")))))))))))))))&" "&IF($U5=$H$38,"(A)",IF($U5=$H$39,"(B)",IF($U5=$H$40,"(C)",IF($U5=$H$41,"(D)",IF($U5=$H$42,"(E)",IF($U5=$H$43,"(F)",IF($U5=$H$44,"(G)",IF($U5=$H$45,"(H)",IF($U5=$H$46,"(I)",IF($U5=$H$47,"(J)",IF($U5=$H$48,"(K)",IF($U5=$H$49,"(L)",IF($U5=$H$50,"(M)",IF($U5=$H$51,"(N)",""))))))))))))))) | AM5: =CONCATENATE(IF($U5=$L$37,$K$37,IF($U5=$L$38,$K$38,IF($U5=$L$39,$K$39,IF($U5=$L$40,$K$40,IF($U5=$L$41,$K$41,IF($U5=$L$42,$K$42,IF($U5=$L$43,$K$43,IF($U5=$L$44,$K$44,IF($U5=$L$45,$K$45,IF($U5=$L$46,$K$46,IF($U5=$L$47,$K$47,IF($U5=$L$48,$K$48,IF($U5=$L$49,$K$49,IF($U5=$L$50,$K$50,IF($U5=$L$51,$K$51,"")))))))))))))))&" "&IF($U5=$L$38,"(A)",IF($U5=$L$39,"(B)",IF($U5=$L$40,"(C)",IF($U5=$L$41,"(D)",IF($U5=$L$42,"(E)",IF($U5=$L$43,"(F)",IF($U5=$L$44,"(G)",IF($U5=$L$45,"(H)",IF($U5=$L$46,"(I)",IF($U5=$L$47,"(J)",IF($U5=$L$48,"(K)",IF($U5=$L$49,"(L)",IF($U5=$L$50,"(M)",IF($U5=$L$51,"(N)",""))))))))))))))) | AN5: =CONCATENATE(IF($U5=$N$37,$M$37,IF($U5=$N$38,$M$38,IF($U5=$N$39,$M$39,IF($U5=$N$40,$M$40,IF($U5=$N$41,$M$41,IF($U5=$N$42,$M$42,IF($U5=$N$43,$M$43,IF($U5=$N$44,$M$44,IF($U5=$N$45,$M$45,IF($U5=$N$46,$M$46,IF($U5=$N$47,$M$47,IF($U5=$N$48,$M$48,IF($U5=$N$49,$M$49,IF($U5=$N$50,$M$50,IF($U5=$N$51,$M$51,"")))))))))))))))&" "&IF($U5=$N$38,"(A)",IF($U5=$N$39,"(B)",IF($U5=$N$40,"(C)",IF($U5=$N$41,"(D)",IF($U5=$N$42,"(E)",IF($U5=$N$43,"(F)",IF($U5=$N$44,"(G)",IF($U5=$N$45,"(H)",IF($U5=$N$46,"(I)",IF($U5=$N$47,"(J)",IF($U5=$N$48,"(K)",IF($U5=$N$49,"(L)",IF($U5=$N$50,"(M)",IF($U5=$N$51,"(N)",""))))))))))))))) | BV5: Balancing of classes
B6: F+ECOM | C6: B | E6: =_xlfn.XLOOKUP(F6, $C$100:$C$107, $D$100:$D$107, "Training") -> IF | F6: (SRN) | G6: =_xlfn.XLOOKUP(H6, $C$100:$C$107, $D$100:$D$107, "Training") -> ECOM | H6: (SR) | K6: =_xlfn.XLOOKUP(L6, $C$100:$C$107, $D$100:$D$107, "Training") -> IT | L6: (UK) | M6: =_xlfn.XLOOKUP(N6, $C$100:$C$107, $D$100:$D$107, "Training") -> FMS | N6: (MS) | O6: =IF(P6="",".",P6) -> . | U6: (AG) | V6: =SUM(COUNTIF($E$5:$N$55,U6),IF(T6<>0,COUNTIF($E$5:$N$55,T6),0),IF(S6<>0,COUNTIF($E$5:$N$55,S6),0)) -> 3 | X6: =U6 -> (AG) | Y6: =SUM((COUNTIF($E$5:$F$55,$U6)),IF($T6<>0,(COUNTIF($E$5:$F$55,$T6))),IF($S6<>0,(COUNTIF($E$5:$F$55,$S6)))) -> 0 | Z6: =SUM(COUNTIF($G$5:$J$55,$U6),IF($T6<>0,(COUNTIF($G$5:$J$55,$T6))),IF($S6<>0,(COUNTIF($G$5:$J$55,$S6)))) -> 1 | AA6: =SUM(COUNTIF($K$5:$L$55,$U6),IF($T6<>0,(COUNTIF($K$5:$L$55,$T6))),IF($S6<>0,(COUNTIF($K$5:$L$55,$S6)))) -> 0 | AB6: =SUM(COUNTIF($M$5:$N$55,$U6),IF($T6<>0,(COUNTIF($M$5:$N$55,$T6))),IF($S6<>0,(COUNTIF($M$5:$N$55,$S6)))) -> 2 | AC6: =CONCATENATE(IF($U6=$F$5,$E$5,IF($U6=$F$6,$E$6,IF($U6=$F$7,$E$7,IF($U6=$F$8,$E$8,IF($U6=$F$9,$E$9,IF($U6=$F$10,$E$10,IF($U6=$F$11,$E$11,IF($U6=$F$12,$E$12,IF($U6=$F$13,$E$13,IF($U6=$F$14,$E$14,IF($U6=$F$15,$E$15,IF($U6=$F$16,$E$16,IF($U6=$F$17,$E$17,"")))))))))))))&" "&IF($U6=$F$5,"(A)",IF($U6=$F$6,"(B)",IF($U6=$F$7,"(C)",IF($U6=$F$8,"(D)",IF($U6=$F$9,"(E)",IF($U6=$F$10,"(F)",IF($U6=$F$11,"(G)",IF($U6=$F$12,"(H)",IF($U6=$F$13,"(I)",IF($U6=$F$14,"(J)",IF($U6=$F$15,"(K)",IF($U6=$F$16,"(L)",IF($U6=$F$17,"(L)","")))))))))))))) | AD6: =CONCATENATE(IF($U6=$H$5,$G$5,IF($U6=$H$6,$G$6,IF($U6=$H$7,$G$7,IF($U6=$H$8,$G$8,IF($U6=$H$9,$G$9,IF($U6=$H$10,$G$10,IF($U6=$H$11,$G$11,IF($U6=$H$12,$G$12,IF($U6=$H$13,$G$13,IF($U6=$H$14,$G$14,IF($U6=$H$15,$G$15,IF($U6=$H$16,$G$16,IF($U6=$H$17,$G$17,"")))))))))))))&" "&IF($U6=$H$5,"(A)",IF($U6=$H$6,"(B)",IF($U6=$H$7,"(C)",IF($U6=$H$8,"(D)",IF($U6=$H$9,"(E)",IF($U6=$H$10,"(F)",IF($U6=$H$11,"(G)",IF($U6=$H$12,"(H)",IF($U6=$H$13,"(I)",IF($U6=$H$14,"(J)",IF($U6=$H$15,"(K)",IF($U6=$H$16,"(L)",IF($U6=$H$17,"(L)","")))))))))))))) | AE6: =CONCATENATE(IF($U6=$L$5,$K$5,IF($U6=$L$6,$K$6,IF($U6=$L$7,$K$7,IF($U6=$L$8,$K$8,IF($U6=$L$9,$K$9,IF($U6=$L$10,$K$10,IF($U6=$L$11,$K$11,IF($U6=$L$12,$K$12,IF($U6=$L$13,$K$13,IF($U6=$L$14,$K$14,IF($U6=$L$15,$K$15,IF($U6=$L$16,$K$16,IF($U6=$L$17,$K$17,"")))))))))))))&" "&IF($U6=$L$5,"(A)",IF($U6=$L$6,"(B)",IF($U6=$L$7,"(C)",IF($U6=$L$8,"(D)",IF($U6=$L$9,"(E)",IF($U6=$L$10,"(F)",IF($U6=$L$11,"(G)",IF($U6=$L$12,"(H)",IF($U6=$L$13,"(I)",IF($U6=$L$14,"(J)",IF($U6=$L$15,"(K)",IF($U6=$L$16,"(L)",IF($U6=$L$17,"(L)","")))))))))))))) | AF6: =CONCATENATE(IF($U6=$N$5,$M$5,IF($U6=$N$6,$M$6,IF($U6=$N$7,$M$7,IF($U6=$N$8,$M$8,IF($U6=$N$9,$M$9,IF($U6=$N$10,$M$10,IF($U6=$N$11,$M$11,IF($U6=$N$12,$M$12,IF($U6=$N$13,$M$13,IF($U6=$N$14,$M$14,IF($U6=$N$15,$M$15,IF($U6=$N$16,$M$16,IF($U6=$N$17,$M$17,"")))))))))))))&" "&(IF($U6=$N$5,"(A)",IF($U6=$N$6,"(B)",IF($U6=$N$7,"(C)",IF($U6=$N$8,"(D)",IF($U6=$N$9,"(E)",IF($U6=$N$10,"(F)",IF($U6=$N$11,"(G)",IF($U6=$N$12,"(H)",IF($U6=$N$13,"(I)",IF($U6=$N$14,"(J)",IF($U6=$N$15,"(K)",IF($U6=$N$16,"(L)",IF($U6=$N$17,"(L)",""))))))))))))))) | AG6: =CONCATENATE(IF($U6=$F$21,$E$21,IF($U6=$F$22,$E$22,IF($U6=$F$23,$E$23,IF($U6=$F$24,$E$24,IF($U6=$F$25,$E$25,IF($U6=$F$26,$E$26,IF($U6=$F$27,$E$27,IF($U6=$F$28,$E$28,IF($U6=$F$29,$E$29,IF($U6=$F$30,$E$30,IF($U6=$F$31,$E$31,IF($U6=$F$32,$E$32,IF($U6=$F$33,$E$33,IF($U6=$F$34,$E$34,"")))))))))))))&" "&(IF($U6=$F$21,"(A)",IF($U6=$F$22,"(B)",IF($U6=$F$23,"(C)",IF($U6=$F$24,"(D)",IF($U6=$F$25,"(E)",IF($U6=$F$26,"(F)",IF($U6=$F$27,"(G)",IF($U6=$F$28,"(H)",IF($U6=$F$29,"(I)",IF($U6=$F$30,"(J)",IF($U6=$D$63,"(K)",IF($U6=$F$32,"(L)",IF($U6=$F$33,"(M)",IF($U6=$F$34,"(N)",""))))))))))))))))) | AH6: =CONCATENATE(IF($U6=$H$21,$G$21,IF($U6=$H$22,$G$22,IF($U6=$H$23,$G$23,IF($U6=$H$24,$G$24,IF($U6=$H$25,$G$25,IF($U6=$H$26,$G$26,IF($U6=$H$27,$G$27,IF($U6=$H$28,$G$28,IF($U6=$H$29,$G$29,IF($U6=$H$30,$G$30,IF($U6=$H$31,$G$31,IF($U6=$H$32,$G$32,IF($U6=$H$33,$G$33,IF($U6=$H$34,$G$34,""))))))))))))))&" "&(IF($U6=$H$21,"(A)",IF($U6=$H$22,"(B)",IF($U6=$H$23,"(C)",IF($U6=$H$24,"(D)",IF($U6=$H$25,"(E)",IF($U6=$H$26,"(F)",IF($U6=$H$27,"(G)",IF($U6=$H$28,"(H)",IF($U6=$H$29,"(I)",IF($U6=$H$30,"(J)",IF($U6=$H$31,"(K)",IF($U6=$H$32,"(L)",IF($U6=$H$33,"(M)",IF($U6=$H$34,"(N)","")))))))))))))))) | AI6: =CONCATENATE(IF($U6=$L$21,$K$21,IF($U6=$L$22,$K$22,IF($U6=$L$23,$K$23,IF($U6=$L$24,$K$24,IF($U6=$L$25,$K$25,IF($U6=$L$26,$K$26,IF($U6=$L$27,$K$27,IF($U6=$L$28,$K$28,IF($U6=$L$29,$K$29,IF($U6=$L$30,$K$30,IF($U6=$L$31,$K$31,IF($U6=$L$32,$K$32,IF($U6=$L$33,$K$33,IF($U6=$L$34,$K$34,""))))))))))))))&" "&IF($U6=$L$21,"(A)",IF($U6=$L$22,"(B)",IF($U6=$L$23,"(C)",IF($U6=$L$24,"(D)",IF($U6=$L$25,"(E)",IF($U6=$L$26,"(F)",IF($U6=$L$27,"(G)",IF($U6=$L$28,"(H)",IF($U6=$L$29,"(I)",IF($U6=$L$30,"(J)",IF($U6=$L$31,"(K)",IF($U6=$L$32,"(L)",IF($U6=$L$33,"(M)",IF($U6=$L$34,"(N)",""))))))))))))))) | AJ6: =CONCATENATE(IF($U6=$N$21,$M$21,IF($U6=$N$22,$M$22,IF($U6=$N$23,$M$23,IF($U6=$N$24,$M$24,IF($U6=$N$25,$M$25,IF($U6=$N$26,$M$26,IF($U6=$N$27,$M$27,IF($U6=$N$28,$M$28,IF($U6=$N$29,$M$29,IF($U6=$N$30,$M$30,IF($U6=$N$31,$M$31,IF($U6=$N$32,$M$32,IF($U6=$N$33,$M$33,IF($U6=$N$34,$M$34,""))))))))))))))&" "&(IF($U6=$N$21,"(A)",IF($U6=$N$22,"(B)",IF($U6=$N$23,"(C)",IF($U6=$N$24,"(D)",IF($U6=$N$25,"(E)",IF($U6=$N$26,"(F)",IF($U6=$N$27,"(G)",IF($U6=$N$28,"(H)",IF($U6=$N$29,"(I)",IF($U6=$N$30,"(J)",IF($U6=$N$31,"(K)",IF($U6=$N$32,"(L)",IF($U6=$N$33,"(M)",IF($U6=$N$34,"(N)","")))))))))))))))) -> EVS (C) | AK6: =CONCATENATE(IF($U6=$F$37,$E$37,IF($U6=$F$38,$E$38,IF($U6=$F$39,$E$39,IF($U6=$F$40,$E$40,IF($U6=$F$41,$E$41,IF($U6=$F$42,$E$42,IF($U6=$F$43,$E$43,IF($U6=$F$44,$E$44,IF($U6=$F$45,$E$45,IF($U6=$F$46,$E$46,IF($U6=$F$47,$E$47,IF($U6=$F$48,$E$48,IF($U6=$F$49,$E$49,IF($U6=$F$50,$E$50,IF($U6=$F$51,$E$51,""))))))))))))))&" "&IF($U6=$F$38,"(A)",IF($U6=$F$39,"(B)",IF($U6=$F$40,"(C)",IF($U6=$F$41,"(D)",IF($U6=$F$42,"(E)",IF($U6=$F$43,"(F)",IF($U6=$F$44,"(G)",IF($U6=$F$45,"(H)",IF($U6=$F$46,"(I)",IF($U6=$F$47,"(J)",IF($U6=$F$48,"(K)",IF($U6=$F$49,"(L)",IF($U6=$F$50,"(M)",IF($U6=$F$51,"(N)","")))))))))))))))) | AL6: =CONCATENATE(IF($U6=$H$37,$G$37,IF($U6=$H$38,$G$38,IF($U6=$H$39,$G$39,IF($U6=$H$40,$G$40,IF($U6=$H$41,$G$41,IF($U6=$H$42,$G$42,IF($U6=$H$43,$G$43,IF($U6=$H$44,$G$44,IF($U6=$H$45,$G$45,IF($U6=$H$46,$G$46,IF($U6=$H$47,$G$47,IF($U6=$H$48,$G$48,IF($U6=$H$49,$G$49,IF($U6=$H$50,$G$50,IF($U6=$H$51,$G$51,"")))))))))))))))&" "&IF($U6=$H$38,"(A)",IF($U6=$H$39,"(B)",IF($U6=$H$40,"(C)",IF($U6=$H$41,"(D)",IF($U6=$H$42,"(E)",IF($U6=$H$43,"(F)",IF($U6=$H$44,"(G)",IF($U6=$H$45,"(H)",IF($U6=$H$46,"(I)",IF($U6=$H$47,"(J)",IF($U6=$H$48,"(K)",IF($U6=$H$49,"(L)",IF($U6=$H$50,"(M)",IF($U6=$H$51,"(N)",""))))))))))))))) -> BM (G) | AM6: =CONCATENATE(IF($U6=$L$37,$K$37,IF($U6=$L$38,$K$38,IF($U6=$L$39,$K$39,IF($U6=$L$40,$K$40,IF($U6=$L$41,$K$41,IF($U6=$L$42,$K$42,IF($U6=$L$43,$K$43,IF($U6=$L$44,$K$44,IF($U6=$L$45,$K$45,IF($U6=$L$46,$K$46,IF($U6=$L$47,$K$47,IF($U6=$L$48,$K$48,IF($U6=$L$49,$K$49,IF($U6=$L$50,$K$50,IF($U6=$L$51,$K$51,"")))))))))))))))&" "&IF($U6=$L$38,"(A)",IF($U6=$L$39,"(B)",IF($U6=$L$40,"(C)",IF($U6=$L$41,"(D)",IF($U6=$L$42,"(E)",IF($U6=$L$43,"(F)",IF($U6=$L$44,"(G)",IF($U6=$L$45,"(H)",IF($U6=$L$46,"(I)",IF($U6=$L$47,"(J)",IF($U6=$L$48,"(K)",IF($U6=$L$49,"(L)",IF($U6=$L$50,"(M)",IF($U6=$L$51,"(N)",""))))))))))))))) | AN6: =CONCATENATE(IF($U6=$N$37,$M$37,IF($U6=$N$38,$M$38,IF($U6=$N$39,$M$39,IF($U6=$N$40,$M$40,IF($U6=$N$41,$M$41,IF($U6=$N$42,$M$42,IF($U6=$N$43,$M$43,IF($U6=$N$44,$M$44,IF($U6=$N$45,$M$45,IF($U6=$N$46,$M$46,IF($U6=$N$47,$M$47,IF($U6=$N$48,$M$48,IF($U6=$N$49,$M$49,IF($U6=$N$50,$M$50,IF($U6=$N$51,$M$51,"")))))))))))))))&" "&IF($U6=$N$38,"(A)",IF($U6=$N$39,"(B)",IF($U6=$N$40,"(C)",IF($U6=$N$41,"(D)",IF($U6=$N$42,"(E)",IF($U6=$N$43,"(F)",IF($U6=$N$44,"(G)",IF($U6=$N$45,"(H)",IF($U6=$N$46,"(I)",IF($U6=$N$47,"(J)",IF($U6=$N$48,"(K)",IF($U6=$N$49,"(L)",IF($U6=$N$50,"(M)",IF($U6=$N$51,"(N)",""))))))))))))))) -> BM (N)
B7: F+ECOM | C7: C | E7: =_xlfn.XLOOKUP(F7, $E$100:$E$107, $F$100:$F$107, "Training") -> ECOM | F7: (AW) | G7: =_xlfn.XLOOKUP(H7, $E$100:$E$107, $F$100:$F$107, "Training") -> MA | H7: (RG) | K7: =_xlfn.XLOOKUP(L7, $E$100:$E$107, $F$100:$F$107, "Training") -> IF | L7: (VAR) | M7: =_xlfn.XLOOKUP(N7, $E$100:$E$107, $F$100:$F$107, "Training") -> IB | N7: (SUN) | O7: =IF(P7="",".",P7) -> . | U7: (ANU) | V7: =SUM(COUNTIF($E$5:$N$55,U7),IF(T7<>0,COUNTIF($E$5:$N$55,T7),0),IF(S7<>0,COUNTIF($E$5:$N$55,S7),0)) -> 0 | X7: =U7 -> (ANU) | Y7: =SUM((COUNTIF($E$5:$F$55,$U7)),IF($T7<>0,(COUNTIF($E$5:$F$55,$T7))),IF($S7<>0,(COUNTIF($E$5:$F$55,$S7)))) -> 0 | Z7: =SUM(COUNTIF($G$5:$J$55,$U7),IF($T7<>0,(COUNTIF($G$5:$J$55,$T7))),IF($S7<>0,(COUNTIF($G$5:$J$55,$S7)))) -> 0 | AA7: =SUM(COUNTIF($K$5:$L$55,$U7),IF($T7<>0,(COUNTIF($K$5:$L$55,$T7))),IF($S7<>0,(COUNTIF($K$5:$L$55,$S7)))) -> 0 | AB7: =SUM(COUNTIF($M$5:$N$55,$U7),IF($T7<>0,(COUNTIF($M$5:$N$55,$T7))),IF($S7<>0,(COUNTIF($M$5:$N$55,$S7)))) -> 0 | AC7: =CONCATENATE(IF($U7=$F$5,$E$5,IF($U7=$F$6,$E$6,IF($U7=$F$7,$E$7,IF($U7=$F$8,$E$8,IF($U7=$F$9,$E$9,IF($U7=$F$10,$E$10,IF($U7=$F$11,$E$11,IF($U7=$F$12,$E$12,IF($U7=$F$13,$E$13,IF($U7=$F$14,$E$14,IF($U7=$F$15,$E$15,IF($U7=$F$16,$E$16,IF($U7=$F$17,$E$17,"")))))))))))))&" "&IF($U7=$F$5,"(A)",IF($U7=$F$6,"(B)",IF($U7=$F$7,"(C)",IF($U7=$F$8,"(D)",IF($U7=$F$9,"(E)",IF($U7=$F$10,"(F)",IF($U7=$F$11,"(G)",IF($U7=$F$12,"(H)",IF($U7=$F$13,"(I)",IF($U7=$F$14,"(J)",IF($U7=$F$15,"(K)",IF($U7=$F$16,"(L)",IF($U7=$F$17,"(L)","")))))))))))))) | AD7: =CONCATENATE(IF($U7=$H$5,$G$5,IF($U7=$H$6,$G$6,IF($U7=$H$7,$G$7,IF($U7=$H$8,$G$8,IF($U7=$H$9,$G$9,IF($U7=$H$10,$G$10,IF($U7=$H$11,$G$11,IF($U7=$H$12,$G$12,IF($U7=$H$13,$G$13,IF($U7=$H$14,$G$14,IF($U7=$H$15,$G$15,IF($U7=$H$16,$G$16,IF($U7=$H$17,$G$17,"")))))))))))))&" "&IF($U7=$H$5,"(A)",IF($U7=$H$6,"(B)",IF($U7=$H$7,"(C)",IF($U7=$H$8,"(D)",IF($U7=$H$9,"(E)",IF($U7=$H$10,"(F)",IF($U7=$H$11,"(G)",IF($U7=$H$12,"(H)",IF($U7=$H$13,"(I)",IF($U7=$H$14,"(J)",IF($U7=$H$15,"(K)",IF($U7=$H$16,"(L)",IF($U7=$H$17,"(L)","")))))))))))))) | AE7: =CONCATENATE(IF($U7=$L$5,$K$5,IF($U7=$L$6,$K$6,IF($U7=$L$7,$K$7,IF($U7=$L$8,$K$8,IF($U7=$L$9,$K$9,IF($U7=$L$10,$K$10,IF($U7=$L$11,$K$11,IF($U7=$L$12,$K$12,IF($U7=$L$13,$K$13,IF($U7=$L$14,$K$14,IF($U7=$L$15,$K$15,IF($U7=$L$16,$K$16,IF($U7=$L$17,$K$17,"")))))))))))))&" "&IF($U7=$L$5,"(A)",IF($U7=$L$6,"(B)",IF($U7=$L$7,"(C)",IF($U7=$L$8,"(D)",IF($U7=$L$9,"(E)",IF($U7=$L$10,"(F)",IF($U7=$L$11,"(G)",IF($U7=$L$12,"(H)",IF($U7=$L$13,"(I)",IF($U7=$L$14,"(J)",IF($U7=$L$15,"(K)",IF($U7=$L$16,"(L)",IF($U7=$L$17,"(L)","")))))))))))))) | AF7: =CONCATENATE(IF($U7=$N$5,$M$5,IF($U7=$N$6,$M$6,IF($U7=$N$7,$M$7,IF($U7=$N$8,$M$8,IF($U7=$N$9,$M$9,IF($U7=$N$10,$M$10,IF($U7=$N$11,$M$11,IF($U7=$N$12,$M$12,IF($U7=$N$13,$M$13,IF($U7=$N$14,$M$14,IF($U7=$N$15,$M$15,IF($U7=$N$16,$M$16,IF($U7=$N$17,$M$17,"")))))))))))))&" "&(IF($U7=$N$5,"(A)",IF($U7=$N$6,"(B)",IF($U7=$N$7,"(C)",IF($U7=$N$8,"(D)",IF($U7=$N$9,"(E)",IF($U7=$N$10,"(F)",IF($U7=$N$11,"(G)",IF($U7=$N$12,"(H)",IF($U7=$N$13,"(I)",IF($U7=$N$14,"(J)",IF($U7=$N$15,"(K)",IF($U7=$N$16,"(L)",IF($U7=$N$17,"(L)",""))))))))))))))) | AG7: =CONCATENATE(IF($U7=$F$21,$E$21,IF($U7=$F$22,$E$22,IF($U7=$F$23,$E$23,IF($U7=$F$24,$E$24,IF($U7=$F$25,$E$25,IF($U7=$F$26,$E$26,IF($U7=$F$27,$E$27,IF($U7=$F$28,$E$28,IF($U7=$F$29,$E$29,IF($U7=$F$30,$E$30,IF($U7=$F$31,$E$31,IF($U7=$F$32,$E$32,IF($U7=$F$33,$E$33,IF($U7=$F$34,$E$34,"")))))))))))))&" "&(IF($U7=$F$21,"(A)",IF($U7=$F$22,"(B)",IF($U7=$F$23,"(C)",IF($U7=$F$24,"(D)",IF($U7=$F$25,"(E)",IF($U7=$F$26,"(F)",IF($U7=$F$27,"(G)",IF($U7=$F$28,"(H)",IF($U7=$F$29,"(I)",IF($U7=$F$30,"(J)",IF($U7=$D$63,"(K)",IF($U7=$F$32,"(L)",IF($U7=$F$33,"(M)",IF($U7=$F$34,"(N)",""))))))))))))))))) | AH7: =CONCATENATE(IF($U7=$H$21,$G$21,IF($U7=$H$22,$G$22,IF($U7=$H$23,$G$23,IF($U7=$H$24,$G$24,IF($U7=$H$25,$G$25,IF($U7=$H$26,$G$26,IF($U7=$H$27,$G$27,IF($U7=$H$28,$G$28,IF($U7=$H$29,$G$29,IF($U7=$H$30,$G$30,IF($U7=$H$31,$G$31,IF($U7=$H$32,$G$32,IF($U7=$H$33,$G$33,IF($U7=$H$34,$G$34,""))))))))))))))&" "&(IF($U7=$H$21,"(A)",IF($U7=$H$22,"(B)",IF($U7=$H$23,"(C)",IF($U7=$H$24,"(D)",IF($U7=$H$25,"(E)",IF($U7=$H$26,"(F)",IF($U7=$H$27,"(G)",IF($U7=$H$28,"(H)",IF($U7=$H$29,"(I)",IF($U7=$H$30,"(J)",IF($U7=$H$31,"(K)",IF($U7=$H$32,"(L)",IF($U7=$H$33,"(M)",IF($U7=$H$34,"(N)","")))))))))))))))) | AI7: =CONCATENATE(IF($U7=$L$21,$K$21,IF($U7=$L$22,$K$22,IF($U7=$L$23,$K$23,IF($U7=$L$24,$K$24,IF($U7=$L$25,$K$25,IF($U7=$L$26,$K$26,IF($U7=$L$27,$K$27,IF($U7=$L$28,$K$28,IF($U7=$L$29,$K$29,IF($U7=$L$30,$K$30,IF($U7=$L$31,$K$31,IF($U7=$L$32,$K$32,IF($U7=$L$33,$K$33,IF($U7=$L$34,$K$34,""))))))))))))))&" "&IF($U7=$L$21,"(A)",IF($U7=$L$22,"(B)",IF($U7=$L$23,"(C)",IF($U7=$L$24,"(D)",IF($U7=$L$25,"(E)",IF($U7=$L$26,"(F)",IF($U7=$L$27,"(G)",IF($U7=$L$28,"(H)",IF($U7=$L$29,"(I)",IF($U7=$L$30,"(J)",IF($U7=$L$31,"(K)",IF($U7=$L$32,"(L)",IF($U7=$L$33,"(M)",IF($U7=$L$34,"(N)",""))))))))))))))) | AJ7: =CONCATENATE(IF($U7=$N$21,$M$21,IF($U7=$N$22,$M$22,IF($U7=$N$23,$M$23,IF($U7=$N$24,$M$24,IF($U7=$N$25,$M$25,IF($U7=$N$26,$M$26,IF($U7=$N$27,$M$27,IF($U7=$N$28,$M$28,IF($U7=$N$29,$M$29,IF($U7=$N$30,$M$30,IF($U7=$N$31,$M$31,IF($U7=$N$32,$M$32,IF($U7=$N$33,$M$33,IF($U7=$N$34,$M$34,""))))))))))))))&" "&(IF($U7=$N$21,"(A)",IF($U7=$N$22,"(B)",IF($U7=$N$23,"(C)",IF($U7=$N$24,"(D)",IF($U7=$N$25,"(E)",IF($U7=$N$26,"(F)",IF($U7=$N$27,"(G)",IF($U7=$N$28,"(H)",IF($U7=$N$29,"(I)",IF($U7=$N$30,"(J)",IF($U7=$N$31,"(K)",IF($U7=$N$32,"(L)",IF($U7=$N$33,"(M)",IF($U7=$N$34,"(N)","")))))))))))))))) | AK7: =CONCATENATE(IF($U7=$F$37,$E$37,IF($U7=$F$38,$E$38,IF($U7=$F$39,$E$39,IF($U7=$F$40,$E$40,IF($U7=$F$41,$E$41,IF($U7=$F$42,$E$42,IF($U7=$F$43,$E$43,IF($U7=$F$44,$E$44,IF($U7=$F$45,$E$45,IF($U7=$F$46,$E$46,IF($U7=$F$47,$E$47,IF($U7=$F$48,$E$48,IF($U7=$F$49,$E$49,IF($U7=$F$50,$E$50,IF($U7=$F$51,$E$51,""))))))))))))))&" "&IF($U7=$F$38,"(A)",IF($U7=$F$39,"(B)",IF($U7=$F$40,"(C)",IF($U7=$F$41,"(D)",IF($U7=$F$42,"(E)",IF($U7=$F$43,"(F)",IF($U7=$F$44,"(G)",IF($U7=$F$45,"(H)",IF($U7=$F$46,"(I)",IF($U7=$F$47,"(J)",IF($U7=$F$48,"(K)",IF($U7=$F$49,"(L)",IF($U7=$F$50,"(M)",IF($U7=$F$51,"(N)","")))))))))))))))) | AL7: =CONCATENATE(IF($U7=$H$37,$G$37,IF($U7=$H$38,$G$38,IF($U7=$H$39,$G$39,IF($U7=$H$40,$G$40,IF($U7=$H$41,$G$41,IF($U7=$H$42,$G$42,IF($U7=$H$43,$G$43,IF($U7=$H$44,$G$44,IF($U7=$H$45,$G$45,IF($U7=$H$46,$G$46,IF($U7=$H$47,$G$47,IF($U7=$H$48,$G$48,IF($U7=$H$49,$G$49,IF($U7=$H$50,$G$50,IF($U7=$H$51,$G$51,"")))))))))))))))&" "&IF($U7=$H$38,"(A)",IF($U7=$H$39,"(B)",IF($U7=$H$40,"(C)",IF($U7=$H$41,"(D)",IF($U7=$H$42,"(E)",IF($U7=$H$43,"(F)",IF($U7=$H$44,"(G)",IF($U7=$H$45,"(H)",IF($U7=$H$46,"(I)",IF($U7=$H$47,"(J)",IF($U7=$H$48,"(K)",IF($U7=$H$49,"(L)",IF($U7=$H$50,"(M)",IF($U7=$H$51,"(N)",""))))))))))))))) | AM7: =CONCATENATE(IF($U7=$L$37,$K$37,IF($U7=$L$38,$K$38,IF($U7=$L$39,$K$39,IF($U7=$L$40,$K$40,IF($U7=$L$41,$K$41,IF($U7=$L$42,$K$42,IF($U7=$L$43,$K$43,IF($U7=$L$44,$K$44,IF($U7=$L$45,$K$45,IF($U7=$L$46,$K$46,IF($U7=$L$47,$K$47,IF($U7=$L$48,$K$48,IF($U7=$L$49,$K$49,IF($U7=$L$50,$K$50,IF($U7=$L$51,$K$51,"")))))))))))))))&" "&IF($U7=$L$38,"(A)",IF($U7=$L$39,"(B)",IF($U7=$L$40,"(C)",IF($U7=$L$41,"(D)",IF($U7=$L$42,"(E)",IF($U7=$L$43,"(F)",IF($U7=$L$44,"(G)",IF($U7=$L$45,"(H)",IF($U7=$L$46,"(I)",IF($U7=$L$47,"(J)",IF($U7=$L$48,"(K)",IF($U7=$L$49,"(L)",IF($U7=$L$50,"(M)",IF($U7=$L$51,"(N)",""))))))))))))))) | AN7: =CONCATENATE(IF($U7=$N$37,$M$37,IF($U7=$N$38,$M$38,IF($U7=$N$39,$M$39,IF($U7=$N$40,$M$40,IF($U7=$N$41,$M$41,IF($U7=$N$42,$M$42,IF($U7=$N$43,$M$43,IF($U7=$N$44,$M$44,IF($U7=$N$45,$M$45,IF($U7=$N$46,$M$46,IF($U7=$N$47,$M$47,IF($U7=$N$48,$M$48,IF($U7=$N$49,$M$49,IF($U7=$N$50,$M$50,IF($U7=$N$51,$M$51,"")))))))))))))))&" "&IF($U7=$N$38,"(A)",IF($U7=$N$39,"(B)",IF($U7=$N$40,"(C)",IF($U7=$N$41,"(D)",IF($U7=$N$42,"(E)",IF($U7=$N$43,"(F)",IF($U7=$N$44,"(G)",IF($U7=$N$45,"(H)",IF($U7=$N$46,"(I)",IF($U7=$N$47,"(J)",IF($U7=$N$48,"(K)",IF($U7=$N$49,"(L)",IF($U7=$N$50,"(M)",IF($U7=$N$51,"(N)","")))))))))))))))
B8: F+ECOM | C8: D | E8: =_xlfn.XLOOKUP(F8, $G$100:$G$107, $H$100:$H$107, "Training") -> FMS | F8: (SUN) | G8: =_xlfn.XLOOKUP(H8, $G$100:$G$107, $H$100:$H$107, "Training") -> IT | H8: (SRN) | K8: =_xlfn.XLOOKUP(L8, $G$100:$G$107, $H$100:$H$107, "Training") -> MA | L8: (MEG) | M8: =_xlfn.XLOOKUP(N8, $G$100:$G$107, $H$100:$H$107, "Training") -> AA | N8: (SUP) | O8: =IF(P8="",".",P8) -> . | U8: (AS) | V8: =SUM(COUNTIF($E$5:$N$55,U8),IF(T8<>0,COUNTIF($E$5:$N$55,T8),0),IF(S8<>0,COUNTIF($E$5:$N$55,S8),0)) -> 3 | X8: =U8 -> (AS) | Y8: =SUM((COUNTIF($E$5:$F$55,$U8)),IF($T8<>0,(COUNTIF($E$5:$F$55,$T8))),IF($S8<>0,(COUNTIF($E$5:$F$55,$S8)))) -> 1 | Z8: =SUM(COUNTIF($G$5:$J$55,$U8),IF($T8<>0,(COUNTIF($G$5:$J$55,$T8))),IF($S8<>0,(COUNTIF($G$5:$J$55,$S8)))) -> 1 | AA8: =SUM(COUNTIF($K$5:$L$55,$U8),IF($T8<>0,(COUNTIF($K$5:$L$55,$T8))),IF($S8<>0,(COUNTIF($K$5:$L$55,$S8)))) -> 1 | AB8: =SUM(COUNTIF($M$5:$N$55,$U8),IF($T8<>0,(COUNTIF($M$5:$N$55,$T8))),IF($S8<>0,(COUNTIF($M$5:$N$55,$S8)))) -> 0 | AC8: =CONCATENATE(IF($U8=$F$5,$E$5,IF($U8=$F$6,$E$6,IF($U8=$F$7,$E$7,IF($U8=$F$8,$E$8,IF($U8=$F$9,$E$9,IF($U8=$F$10,$E$10,IF($U8=$F$11,$E$11,IF($U8=$F$12,$E$12,IF($U8=$F$13,$E$13,IF($U8=$F$14,$E$14,IF($U8=$F$15,$E$15,IF($U8=$F$16,$E$16,IF($U8=$F$17,$E$17,"")))))))))))))&" "&IF($U8=$F$5,"(A)",IF($U8=$F$6,"(B)",IF($U8=$F$7,"(C)",IF($U8=$F$8,"(D)",IF($U8=$F$9,"(E)",IF($U8=$F$10,"(F)",IF($U8=$F$11,"(G)",IF($U8=$F$12,"(H)",IF($U8=$F$13,"(I)",IF($U8=$F$14,"(J)",IF($U8=$F$15,"(K)",IF($U8=$F$16,"(L)",IF($U8=$F$17,"(L)","")))))))))))))) | AD8: =CONCATENATE(IF($U8=$H$5,$G$5,IF($U8=$H$6,$G$6,IF($U8=$H$7,$G$7,IF($U8=$H$8,$G$8,IF($U8=$H$9,$G$9,IF($U8=$H$10,$G$10,IF($U8=$H$11,$G$11,IF($U8=$H$12,$G$12,IF($U8=$H$13,$G$13,IF($U8=$H$14,$G$14,IF($U8=$H$15,$G$15,IF($U8=$H$16,$G$16,IF($U8=$H$17,$G$17,"")))))))))))))&" "&IF($U8=$H$5,"(A)",IF($U8=$H$6,"(B)",IF($U8=$H$7,"(C)",IF($U8=$H$8,"(D)",IF($U8=$H$9,"(E)",IF($U8=$H$10,"(F)",IF($U8=$H$11,"(G)",IF($U8=$H$12,"(H)",IF($U8=$H$13,"(I)",IF($U8=$H$14,"(J)",IF($U8=$H$15,"(K)",IF($U8=$H$16,"(L)",IF($U8=$H$17,"(L)","")))))))))))))) | AE8: =CONCATENATE(IF($U8=$L$5,$K$5,IF($U8=$L$6,$K$6,IF($U8=$L$7,$K$7,IF($U8=$L$8,$K$8,IF($U8=$L$9,$K$9,IF($U8=$L$10,$K$10,IF($U8=$L$11,$K$11,IF($U8=$L$12,$K$12,IF($U8=$L$13,$K$13,IF($U8=$L$14,$K$14,IF($U8=$L$15,$K$15,IF($U8=$L$16,$K$16,IF($U8=$L$17,$K$17,"")))))))))))))&" "&IF($U8=$L$5,"(A)",IF($U8=$L$6,"(B)",IF($U8=$L$7,"(C)",IF($U8=$L$8,"(D)",IF($U8=$L$9,"(E)",IF($U8=$L$10,"(F)",IF($U8=$L$11,"(G)",IF($U8=$L$12,"(H)",IF($U8=$L$13,"(I)",IF($U8=$L$14,"(J)",IF($U8=$L$15,"(K)",IF($U8=$L$16,"(L)",IF($U8=$L$17,"(L)","")))))))))))))) | AF8: =CONCATENATE(IF($U8=$N$5,$M$5,IF($U8=$N$6,$M$6,IF($U8=$N$7,$M$7,IF($U8=$N$8,$M$8,IF($U8=$N$9,$M$9,IF($U8=$N$10,$M$10,IF($U8=$N$11,$M$11,IF($U8=$N$12,$M$12,IF($U8=$N$13,$M$13,IF($U8=$N$14,$M$14,IF($U8=$N$15,$M$15,IF($U8=$N$16,$M$16,IF($U8=$N$17,$M$17,"")))))))))))))&" "&(IF($U8=$N$5,"(A)",IF($U8=$N$6,"(B)",IF($U8=$N$7,"(C)",IF($U8=$N$8,"(D)",IF($U8=$N$9,"(E)",IF($U8=$N$10,"(F)",IF($U8=$N$11,"(G)",IF($U8=$N$12,"(H)",IF($U8=$N$13,"(I)",IF($U8=$N$14,"(J)",IF($U8=$N$15,"(K)",IF($U8=$N$16,"(L)",IF($U8=$N$17,"(L)",""))))))))))))))) | AG8: =CONCATENATE(IF($U8=$F$21,$E$21,IF($U8=$F$22,$E$22,IF($U8=$F$23,$E$23,IF($U8=$F$24,$E$24,IF($U8=$F$25,$E$25,IF($U8=$F$26,$E$26,IF($U8=$F$27,$E$27,IF($U8=$F$28,$E$28,IF($U8=$F$29,$E$29,IF($U8=$F$30,$E$30,IF($U8=$F$31,$E$31,IF($U8=$F$32,$E$32,IF($U8=$F$33,$E$33,IF($U8=$F$34,$E$34,"")))))))))))))&" "&(IF($U8=$F$21,"(A)",IF($U8=$F$22,"(B)",IF($U8=$F$23,"(C)",IF($U8=$F$24,"(D)",IF($U8=$F$25,"(E)",IF($U8=$F$26,"(F)",IF($U8=$F$27,"(G)",IF($U8=$F$28,"(H)",IF($U8=$F$29,"(I)",IF($U8=$F$30,"(J)",IF($U8=$D$63,"(K)",IF($U8=$F$32,"(L)",IF($U8=$F$33,"(M)",IF($U8=$F$34,"(N)",""))))))))))))))))) -> HR | AH8: =CONCATENATE(IF($U8=$H$21,$G$21,IF($U8=$H$22,$G$22,IF($U8=$H$23,$G$23,IF($U8=$H$24,$G$24,IF($U8=$H$25,$G$25,IF($U8=$H$26,$G$26,IF($U8=$H$27,$G$27,IF($U8=$H$28,$G$28,IF($U8=$H$29,$G$29,IF($U8=$H$30,$G$30,IF($U8=$H$31,$G$31,IF($U8=$H$32,$G$32,IF($U8=$H$33,$G$33,IF($U8=$H$34,$G$34,""))))))))))))))&" "&(IF($U8=$H$21,"(A)",IF($U8=$H$22,"(B)",IF($U8=$H$23,"(C)",IF($U8=$H$24,"(D)",IF($U8=$H$25,"(E)",IF($U8=$H$26,"(F)",IF($U8=$H$27,"(G)",IF($U8=$H$28,"(H)",IF($U8=$H$29,"(I)",IF($U8=$H$30,"(J)",IF($U8=$H$31,"(K)",IF($U8=$H$32,"(L)",IF($U8=$H$33,"(M)",IF($U8=$H$34,"(N)","")))))))))))))))) | AI8: =CONCATENATE(IF($U8=$L$21,$K$21,IF($U8=$L$22,$K$22,IF($U8=$L$23,$K$23,IF($U8=$L$24,$K$24,IF($U8=$L$25,$K$25,IF($U8=$L$26,$K$26,IF($U8=$L$27,$K$27,IF($U8=$L$28,$K$28,IF($U8=$L$29,$K$29,IF($U8=$L$30,$K$30,IF($U8=$L$31,$K$31,IF($U8=$L$32,$K$32,IF($U8=$L$33,$K$33,IF($U8=$L$34,$K$34,""))))))))))))))&" "&IF($U8=$L$21,"(A)",IF($U8=$L$22,"(B)",IF($U8=$L$23,"(C)",IF($U8=$L$24,"(D)",IF($U8=$L$25,"(E)",IF($U8=$L$26,"(F)",IF($U8=$L$27,"(G)",IF($U8=$L$28,"(H)",IF($U8=$L$29,"(I)",IF($U8=$L$30,"(J)",IF($U8=$L$31,"(K)",IF($U8=$L$32,"(L)",IF($U8=$L$33,"(M)",IF($U8=$L$34,"(N)",""))))))))))))))) -> HR (G) | AJ8: =CONCATENATE(IF($U8=$N$21,$M$21,IF($U8=$N$22,$M$22,IF($U8=$N$23,$M$23,IF($U8=$N$24,$M$24,IF($U8=$N$25,$M$25,IF($U8=$N$26,$M$26,IF($U8=$N$27,$M$27,IF($U8=$N$28,$M$28,IF($U8=$N$29,$M$29,IF($U8=$N$30,$M$30,IF($U8=$N$31,$M$31,IF($U8=$N$32,$M$32,IF($U8=$N$33,$M$33,IF($U8=$N$34,$M$34,""))))))))))))))&" "&(IF($U8=$N$21,"(A)",IF($U8=$N$22,"(B)",IF($U8=$N$23,"(C)",IF($U8=$N$24,"(D)",IF($U8=$N$25,"(E)",IF($U8=$N$26,"(F)",IF($U8=$N$27,"(G)",IF($U8=$N$28,"(H)",IF($U8=$N$29,"(I)",IF($U8=$N$30,"(J)",IF($U8=$N$31,"(K)",IF($U8=$N$32,"(L)",IF($U8=$N$33,"(M)",IF($U8=$N$34,"(N)","")))))))))))))))) | AK8: =CONCATENATE(IF($U8=$F$37,$E$37,IF($U8=$F$38,$E$38,IF($U8=$F$39,$E$39,IF($U8=$F$40,$E$40,IF($U8=$F$41,$E$41,IF($U8=$F$42,$E$42,IF($U8=$F$43,$E$43,IF($U8=$F$44,$E$44,IF($U8=$F$45,$E$45,IF($U8=$F$46,$E$46,IF($U8=$F$47,$E$47,IF($U8=$F$48,$E$48,IF($U8=$F$49,$E$49,IF($U8=$F$50,$E$50,IF($U8=$F$51,$E$51,""))))))))))))))&" "&IF($U8=$F$38,"(A)",IF($U8=$F$39,"(B)",IF($U8=$F$40,"(C)",IF($U8=$F$41,"(D)",IF($U8=$F$42,"(E)",IF($U8=$F$43,"(F)",IF($U8=$F$44,"(G)",IF($U8=$F$45,"(H)",IF($U8=$F$46,"(I)",IF($U8=$F$47,"(J)",IF($U8=$F$48,"(K)",IF($U8=$F$49,"(L)",IF($U8=$F$50,"(M)",IF($U8=$F$51,"(N)","")))))))))))))))) | AL8: =CONCATENATE(IF($U8=$H$37,$G$37,IF($U8=$H$38,$G$38,IF($U8=$H$39,$G$39,IF($U8=$H$40,$G$40,IF($U8=$H$41,$G$41,IF($U8=$H$42,$G$42,IF($U8=$H$43,$G$43,IF($U8=$H$44,$G$44,IF($U8=$H$45,$G$45,IF($U8=$H$46,$G$46,IF($U8=$H$47,$G$47,IF($U8=$H$48,$G$48,IF($U8=$H$49,$G$49,IF($U8=$H$50,$G$50,IF($U8=$H$51,$G$51,"")))))))))))))))&" "&IF($U8=$H$38,"(A)",IF($U8=$H$39,"(B)",IF($U8=$H$40,"(C)",IF($U8=$H$41,"(D)",IF($U8=$H$42,"(E)",IF($U8=$H$43,"(F)",IF($U8=$H$44,"(G)",IF($U8=$H$45,"(H)",IF($U8=$H$46,"(I)",IF($U8=$H$47,"(J)",IF($U8=$H$48,"(K)",IF($U8=$H$49,"(L)",IF($U8=$H$50,"(M)",IF($U8=$H$51,"(N)",""))))))))))))))) -> BM (A) | AM8: =CONCATENATE(IF($U8=$L$37,$K$37,IF($U8=$L$38,$K$38,IF($U8=$L$39,$K$39,IF($U8=$L$40,$K$40,IF($U8=$L$41,$K$41,IF($U8=$L$42,$K$42,IF($U8=$L$43,$K$43,IF($U8=$L$44,$K$44,IF($U8=$L$45,$K$45,IF($U8=$L$46,$K$46,IF($U8=$L$47,$K$47,IF($U8=$L$48,$K$48,IF($U8=$L$49,$K$49,IF($U8=$L$50,$K$50,IF($U8=$L$51,$K$51,"")))))))))))))))&" "&IF($U8=$L$38,"(A)",IF($U8=$L$39,"(B)",IF($U8=$L$40,"(C)",IF($U8=$L$41,"(D)",IF($U8=$L$42,"(E)",IF($U8=$L$43,"(F)",IF($U8=$L$44,"(G)",IF($U8=$L$45,"(H)",IF($U8=$L$46,"(I)",IF($U8=$L$47,"(J)",IF($U8=$L$48,"(K)",IF($U8=$L$49,"(L)",IF($U8=$L$50,"(M)",IF($U8=$L$51,"(N)",""))))))))))))))) | AN8: =CONCATENATE(IF($U8=$N$37,$M$37,IF($U8=$N$38,$M$38,IF($U8=$N$39,$M$39,IF($U8=$N$40,$M$40,IF($U8=$N$41,$M$41,IF($U8=$N$42,$M$42,IF($U8=$N$43,$M$43,IF($U8=$N$44,$M$44,IF($U8=$N$45,$M$45,IF($U8=$N$46,$M$46,IF($U8=$N$47,$M$47,IF($U8=$N$48,$M$48,IF($U8=$N$49,$M$49,IF($U8=$N$50,$M$50,IF($U8=$N$51,$M$51,"")))))))))))))))&" "&IF($U8=$N$38,"(A)",IF($U8=$N$39,"(B)",IF($U8=$N$40,"(C)",IF($U8=$N$41,"(D)",IF($U8=$N$42,"(E)",IF($U8=$N$43,"(F)",IF($U8=$N$44,"(G)",IF($U8=$N$45,"(H)",IF($U8=$N$46,"(I)",IF($U8=$N$47,"(J)",IF($U8=$N$48,"(K)",IF($U8=$N$49,"(L)",IF($U8=$N$50,"(M)",IF($U8=$N$51,"(N)","")))))))))))))))
B9: F+ECOM | C9: E | E9: =_xlfn.XLOOKUP(F9, $I$100:$I$107, $J$100:$J$107, "Training") -> IT | F9: (AD) | G9: =_xlfn.XLOOKUP(H9, $I$100:$I$107, $J$100:$J$107, "Training") -> MA | H9: (KR) | K9: =_xlfn.XLOOKUP(L9, $I$100:$I$107, $J$100:$J$107, "Training") -> ECOM | L9: (DT) | M9: =_xlfn.XLOOKUP(N9, $I$100:$I$107, $J$100:$J$107, "Training") -> IB | N9: (EC) | O9: =IF(P9="",".",P9) -> . | U9: (AV) | V9: =SUM(COUNTIF($E$5:$N$55,U9),IF(T9<>0,COUNTIF($E$5:$N$55,T9),0),IF(S9<>0,COUNTIF($E$5:$N$55,S9),0)) -> 2 | X9: =U9 -> (AV) | Y9: =SUM((COUNTIF($E$5:$F$55,$U9)),IF($T9<>0,(COUNTIF($E$5:$F$55,$T9))),IF($S9<>0,(COUNTIF($E$5:$F$55,$S9)))) -> 1 | Z9: =SUM(COUNTIF($G$5:$J$55,$U9),IF($T9<>0,(COUNTIF($G$5:$J$55,$T9))),IF($S9<>0,(COUNTIF($G$5:$J$55,$S9)))) -> 0 | AA9: =SUM(COUNTIF($K$5:$L$55,$U9),IF($T9<>0,(COUNTIF($K$5:$L$55,$T9))),IF($S9<>0,(COUNTIF($K$5:$L$55,$S9)))) -> 1 | AB9: =SUM(COUNTIF($M$5:$N$55,$U9),IF($T9<>0,(COUNTIF($M$5:$N$55,$T9))),IF($S9<>0,(COUNTIF($M$5:$N$55,$S9)))) -> 0 | AC9: =CONCATENATE(IF($U9=$F$5,$E$5,IF($U9=$F$6,$E$6,IF($U9=$F$7,$E$7,IF($U9=$F$8,$E$8,IF($U9=$F$9,$E$9,IF($U9=$F$10,$E$10,IF($U9=$F$11,$E$11,IF($U9=$F$12,$E$12,IF($U9=$F$13,$E$13,IF($U9=$F$14,$E$14,IF($U9=$F$15,$E$15,IF($U9=$F$16,$E$16,IF($U9=$F$17,$E$17,"")))))))))))))&" "&IF($U9=$F$5,"(A)",IF($U9=$F$6,"(B)",IF($U9=$F$7,"(C)",IF($U9=$F$8,"(D)",IF($U9=$F$9,"(E)",IF($U9=$F$10,"(F)",IF($U9=$F$11,"(G)",IF($U9=$F$12,"(H)",IF($U9=$F$13,"(I)",IF($U9=$F$14,"(J)",IF($U9=$F$15,"(K)",IF($U9=$F$16,"(L)",IF($U9=$F$17,"(L)","")))))))))))))) -> IB (L) | AD9: =CONCATENATE(IF($U9=$H$5,$G$5,IF($U9=$H$6,$G$6,IF($U9=$H$7,$G$7,IF($U9=$H$8,$G$8,IF($U9=$H$9,$G$9,IF($U9=$H$10,$G$10,IF($U9=$H$11,$G$11,IF($U9=$H$12,$G$12,IF($U9=$H$13,$G$13,IF($U9=$H$14,$G$14,IF($U9=$H$15,$G$15,IF($U9=$H$16,$G$16,IF($U9=$H$17,$G$17,"")))))))))))))&" "&IF($U9=$H$5,"(A)",IF($U9=$H$6,"(B)",IF($U9=$H$7,"(C)",IF($U9=$H$8,"(D)",IF($U9=$H$9,"(E)",IF($U9=$H$10,"(F)",IF($U9=$H$11,"(G)",IF($U9=$H$12,"(H)",IF($U9=$H$13,"(I)",IF($U9=$H$14,"(J)",IF($U9=$H$15,"(K)",IF($U9=$H$16,"(L)",IF($U9=$H$17,"(L)","")))))))))))))) | AE9: =CONCATENATE(IF($U9=$L$5,$K$5,IF($U9=$L$6,$K$6,IF($U9=$L$7,$K$7,IF($U9=$L$8,$K$8,IF($U9=$L$9,$K$9,IF($U9=$L$10,$K$10,IF($U9=$L$11,$K$11,IF($U9=$L$12,$K$12,IF($U9=$L$13,$K$13,IF($U9=$L$14,$K$14,IF($U9=$L$15,$K$15,IF($U9=$L$16,$K$16,IF($U9=$L$17,$K$17,"")))))))))))))&" "&IF($U9=$L$5,"(A)",IF($U9=$L$6,"(B)",IF($U9=$L$7,"(C)",IF($U9=$L$8,"(D)",IF($U9=$L$9,"(E)",IF($U9=$L$10,"(F)",IF($U9=$L$11,"(G)",IF($U9=$L$12,"(H)",IF($U9=$L$13,"(I)",IF($U9=$L$14,"(J)",IF($U9=$L$15,"(K)",IF($U9=$L$16,"(L)",IF($U9=$L$17,"(L)","")))))))))))))) -> MIP (J) | AF9: =CONCATENATE(IF($U9=$N$5,$M$5,IF($U9=$N$6,$M$6,IF($U9=$N$7,$M$7,IF($U9=$N$8,$M$8,IF($U9=$N$9,$M$9,IF($U9=$N$10,$M$10,IF($U9=$N$11,$M$11,IF($U9=$N$12,$M$12,IF($U9=$N$13,$M$13,IF($U9=$N$14,$M$14,IF($U9=$N$15,$M$15,IF($U9=$N$16,$M$16,IF($U9=$N$17,$M$17,"")))))))))))))&" "&(IF($U9=$N$5,"(A)",IF($U9=$N$6,"(B)",IF($U9=$N$7,"(C)",IF($U9=$N$8,"(D)",IF($U9=$N$9,"(E)",IF($U9=$N$10,"(F)",IF($U9=$N$11,"(G)",IF($U9=$N$12,"(H)",IF($U9=$N$13,"(I)",IF($U9=$N$14,"(J)",IF($U9=$N$15,"(K)",IF($U9=$N$16,"(L)",IF($U9=$N$17,"(L)",""))))))))))))))) | AG9: =CONCATENATE(IF($U9=$F$21,$E$21,IF($U9=$F$22,$E$22,IF($U9=$F$23,$E$23,IF($U9=$F$24,$E$24,IF($U9=$F$25,$E$25,IF($U9=$F$26,$E$26,IF($U9=$F$27,$E$27,IF($U9=$F$28,$E$28,IF($U9=$F$29,$E$29,IF($U9=$F$30,$E$30,IF($U9=$F$31,$E$31,IF($U9=$F$32,$E$32,IF($U9=$F$33,$E$33,IF($U9=$F$34,$E$34,"")))))))))))))&" "&(IF($U9=$F$21,"(A)",IF($U9=$F$22,"(B)",IF($U9=$F$23,"(C)",IF($U9=$F$24,"(D)",IF($U9=$F$25,"(E)",IF($U9=$F$26,"(F)",IF($U9=$F$27,"(G)",IF($U9=$F$28,"(H)",IF($U9=$F$29,"(I)",IF($U9=$F$30,"(J)",IF($U9=$D$63,"(K)",IF($U9=$F$32,"(L)",IF($U9=$F$33,"(M)",IF($U9=$F$34,"(N)",""))))))))))))))))) | AH9: =CONCATENATE(IF($U9=$H$21,$G$21,IF($U9=$H$22,$G$22,IF($U9=$H$23,$G$23,IF($U9=$H$24,$G$24,IF($U9=$H$25,$G$25,IF($U9=$H$26,$G$26,IF($U9=$H$27,$G$27,IF($U9=$H$28,$G$28,IF($U9=$H$29,$G$29,IF($U9=$H$30,$G$30,IF($U9=$H$31,$G$31,IF($U9=$H$32,$G$32,IF($U9=$H$33,$G$33,IF($U9=$H$34,$G$34,""))))))))))))))&" "&(IF($U9=$H$21,"(A)",IF($U9=$H$22,"(B)",IF($U9=$H$23,"(C)",IF($U9=$H$24,"(D)",IF($U9=$H$25,"(E)",IF($U9=$H$26,"(F)",IF($U9=$H$27,"(G)",IF($U9=$H$28,"(H)",IF($U9=$H$29,"(I)",IF($U9=$H$30,"(J)",IF($U9=$H$31,"(K)",IF($U9=$H$32,"(L)",IF($U9=$H$33,"(M)",IF($U9=$H$34,"(N)","")))))))))))))))) | AI9: =CONCATENATE(IF($U9=$L$21,$K$21,IF($U9=$L$22,$K$22,IF($U9=$L$23,$K$23,IF($U9=$L$24,$K$24,IF($U9=$L$25,$K$25,IF($U9=$L$26,$K$26,IF($U9=$L$27,$K$27,IF($U9=$L$28,$K$28,IF($U9=$L$29,$K$29,IF($U9=$L$30,$K$30,IF($U9=$L$31,$K$31,IF($U9=$L$32,$K$32,IF($U9=$L$33,$K$33,IF($U9=$L$34,$K$34,""))))))))))))))&" "&IF($U9=$L$21,"(A)",IF($U9=$L$22,"(B)",IF($U9=$L$23,"(C)",IF($U9=$L$24,"(D)",IF($U9=$L$25,"(E)",IF($U9=$L$26,"(F)",IF($U9=$L$27,"(G)",IF($U9=$L$28,"(H)",IF($U9=$L$29,"(I)",IF($U9=$L$30,"(J)",IF($U9=$L$31,"(K)",IF($U9=$L$32,"(L)",IF($U9=$L$33,"(M)",IF($U9=$L$34,"(N)",""))))))))))))))) | AJ9: =CONCATENATE(IF($U9=$N$21,$M$21,IF($U9=$N$22,$M$22,IF($U9=$N$23,$M$23,IF($U9=$N$24,$M$24,IF($U9=$N$25,$M$25,IF($U9=$N$26,$M$26,IF($U9=$N$27,$M$27,IF($U9=$N$28,$M$28,IF($U9=$N$29,$M$29,IF($U9=$N$30,$M$30,IF($U9=$N$31,$M$31,IF($U9=$N$32,$M$32,IF($U9=$N$33,$M$33,IF($U9=$N$34,$M$34,""))))))))))))))&" "&(IF($U9=$N$21,"(A)",IF($U9=$N$22,"(B)",IF($U9=$N$23,"(C)",IF($U9=$N$24,"(D)",IF($U9=$N$25,"(E)",IF($U9=$N$26,"(F)",IF($U9=$N$27,"(G)",IF($U9=$N$28,"(H)",IF($U9=$N$29,"(I)",IF($U9=$N$30,"(J)",IF($U9=$N$31,"(K)",IF($U9=$N$32,"(L)",IF($U9=$N$33,"(M)",IF($U9=$N$34,"(N)","")))))))))))))))) | AK9: =CONCATENATE(IF($U9=$F$37,$E$37,IF($U9=$F$38,$E$38,IF($U9=$F$39,$E$39,IF($U9=$F$40,$E$40,IF($U9=$F$41,$E$41,IF($U9=$F$42,$E$42,IF($U9=$F$43,$E$43,IF($U9=$F$44,$E$44,IF($U9=$F$45,$E$45,IF($U9=$F$46,$E$46,IF($U9=$F$47,$E$47,IF($U9=$F$48,$E$48,IF($U9=$F$49,$E$49,IF($U9=$F$50,$E$50,IF($U9=$F$51,$E$51,""))))))))))))))&" "&IF($U9=$F$38,"(A)",IF($U9=$F$39,"(B)",IF($U9=$F$40,"(C)",IF($U9=$F$41,"(D)",IF($U9=$F$42,"(E)",IF($U9=$F$43,"(F)",IF($U9=$F$44,"(G)",IF($U9=$F$45,"(H)",IF($U9=$F$46,"(I)",IF($U9=$F$47,"(J)",IF($U9=$F$48,"(K)",IF($U9=$F$49,"(L)",IF($U9=$F$50,"(M)",IF($U9=$F$51,"(N)","")))))))))))))))) | AL9: =CONCATENATE(IF($U9=$H$37,$G$37,IF($U9=$H$38,$G$38,IF($U9=$H$39,$G$39,IF($U9=$H$40,$G$40,IF($U9=$H$41,$G$41,IF($U9=$H$42,$G$42,IF($U9=$H$43,$G$43,IF($U9=$H$44,$G$44,IF($U9=$H$45,$G$45,IF($U9=$H$46,$G$46,IF($U9=$H$47,$G$47,IF($U9=$H$48,$G$48,IF($U9=$H$49,$G$49,IF($U9=$H$50,$G$50,IF($U9=$H$51,$G$51,"")))))))))))))))&" "&IF($U9=$H$38,"(A)",IF($U9=$H$39,"(B)",IF($U9=$H$40,"(C)",IF($U9=$H$41,"(D)",IF($U9=$H$42,"(E)",IF($U9=$H$43,"(F)",IF($U9=$H$44,"(G)",IF($U9=$H$45,"(H)",IF($U9=$H$46,"(I)",IF($U9=$H$47,"(J)",IF($U9=$H$48,"(K)",IF($U9=$H$49,"(L)",IF($U9=$H$50,"(M)",IF($U9=$H$51,"(N)",""))))))))))))))) | AM9: =CONCATENATE(IF($U9=$L$37,$K$37,IF($U9=$L$38,$K$38,IF($U9=$L$39,$K$39,IF($U9=$L$40,$K$40,IF($U9=$L$41,$K$41,IF($U9=$L$42,$K$42,IF($U9=$L$43,$K$43,IF($U9=$L$44,$K$44,IF($U9=$L$45,$K$45,IF($U9=$L$46,$K$46,IF($U9=$L$47,$K$47,IF($U9=$L$48,$K$48,IF($U9=$L$49,$K$49,IF($U9=$L$50,$K$50,IF($U9=$L$51,$K$51,"")))))))))))))))&" "&IF($U9=$L$38,"(A)",IF($U9=$L$39,"(B)",IF($U9=$L$40,"(C)",IF($U9=$L$41,"(D)",IF($U9=$L$42,"(E)",IF($U9=$L$43,"(F)",IF($U9=$L$44,"(G)",IF($U9=$L$45,"(H)",IF($U9=$L$46,"(I)",IF($U9=$L$47,"(J)",IF($U9=$L$48,"(K)",IF($U9=$L$49,"(L)",IF($U9=$L$50,"(M)",IF($U9=$L$51,"(N)",""))))))))))))))) | AN9: =CONCATENATE(IF($U9=$N$37,$M$37,IF($U9=$N$38,$M$38,IF($U9=$N$39,$M$39,IF($U9=$N$40,$M$40,IF($U9=$N$41,$M$41,IF($U9=$N$42,$M$42,IF($U9=$N$43,$M$43,IF($U9=$N$44,$M$44,IF($U9=$N$45,$M$45,IF($U9=$N$46,$M$46,IF($U9=$N$47,$M$47,IF($U9=$N$48,$M$48,IF($U9=$N$49,$M$49,IF($U9=$N$50,$M$50,IF($U9=$N$51,$M$51,"")))))))))))))))&" "&IF($U9=$N$38,"(A)",IF($U9=$N$39,"(B)",IF($U9=$N$40,"(C)",IF($U9=$N$41,"(D)",IF($U9=$N$42,"(E)",IF($U9=$N$43,"(F)",IF($U9=$N$44,"(G)",IF($U9=$N$45,"(H)",IF($U9=$N$46,"(I)",IF($U9=$N$47,"(J)",IF($U9=$N$48,"(K)",IF($U9=$N$49,"(L)",IF($U9=$N$50,"(M)",IF($U9=$N$51,"(N)","")))))))))))))))
B10: F+PR | C10: F | E10: =_xlfn.XLOOKUP(F10, $K$100:$K$107, $L$100:$L$107, "Training") -> AA | F10: (MS) | G10: =_xlfn.XLOOKUP(H10, $K$100:$K$107, $L$100:$L$107, "Training") -> IT | H10: (UK) | K10: =_xlfn.XLOOKUP(L10, $K$100:$K$107, $L$100:$L$107, "Training") -> FMS | L10: (NG) | M10: =_xlfn.XLOOKUP(N10, $K$100:$K$107, $L$100:$L$107, "Training") -> IF | N10: (VAR) | O10: =IF(P10="",".",P10) -> Unplanned | P10: Unplanned | U10: (AW) | V10: =SUM(COUNTIF($E$5:$N$55,U10),IF(T10<>0,COUNTIF($E$5:$N$55,T10),0),IF(S10<>0,COUNTIF($E$5:$N$55,S10),0)) -> 3 | X10: =U10 -> (AW) | Y10: =SUM((COUNTIF($E$5:$F$55,$U10)),IF($T10<>0,(COUNTIF($E$5:$F$55,$T10))),IF($S10<>0,(COUNTIF($E$5:$F$55,$S10)))) -> 2 | Z10: =SUM(COUNTIF($G$5:$J$55,$U10),IF($T10<>0,(COUNTIF($G$5:$J$55,$T10))),IF($S10<>0,(COUNTIF($G$5:$J$55,$S10)))) -> 0 | AA10: =SUM(COUNTIF($K$5:$L$55,$U10),IF($T10<>0,(COUNTIF($K$5:$L$55,$T10))),IF($S10<>0,(COUNTIF($K$5:$L$55,$S10)))) -> 1 | AB10: =SUM(COUNTIF($M$5:$N$55,$U10),IF($T10<>0,(COUNTIF($M$5:$N$55,$T10))),IF($S10<>0,(COUNTIF($M$5:$N$55,$S10)))) -> 0 | AC10: =CONCATENATE(IF($U10=$F$5,$E$5,IF($U10=$F$6,$E$6,IF($U10=$F$7,$E$7,IF($U10=$F$8,$E$8,IF($U10=$F$9,$E$9,IF($U10=$F$10,$E$10,IF($U10=$F$11,$E$11,IF($U10=$F$12,$E$12,IF($U10=$F$13,$E$13,IF($U10=$F$14,$E$14,IF($U10=$F$15,$E$15,IF($U10=$F$16,$E$16,IF($U10=$F$17,$E$17,"")))))))))))))&" "&IF($U10=$F$5,"(A)",IF($U10=$F$6,"(B)",IF($U10=$F$7,"(C)",IF($U10=$F$8,"(D)",IF($U10=$F$9,"(E)",IF($U10=$F$10,"(F)",IF($U10=$F$11,"(G)",IF($U10=$F$12,"(H)",IF($U10=$F$13,"(I)",IF($U10=$F$14,"(J)",IF($U10=$F$15,"(K)",IF($U10=$F$16,"(L)",IF($U10=$F$17,"(L)","")))))))))))))) -> ECOM (C) | AD10: =CONCATENATE(IF($U10=$H$5,$G$5,IF($U10=$H$6,$G$6,IF($U10=$H$7,$G$7,IF($U10=$H$8,$G$8,IF($U10=$H$9,$G$9,IF($U10=$H$10,$G$10,IF($U10=$H$11,$G$11,IF($U10=$H$12,$G$12,IF($U10=$H$13,$G$13,IF($U10=$H$14,$G$14,IF($U10=$H$15,$G$15,IF($U10=$H$16,$G$16,IF($U10=$H$17,$G$17,"")))))))))))))&" "&IF($U10=$H$5,"(A)",IF($U10=$H$6,"(B)",IF($U10=$H$7,"(C)",IF($U10=$H$8,"(D)",IF($U10=$H$9,"(E)",IF($U10=$H$10,"(F)",IF($U10=$H$11,"(G)",IF($U10=$H$12,"(H)",IF($U10=$H$13,"(I)",IF($U10=$H$14,"(J)",IF($U10=$H$15,"(K)",IF($U10=$H$16,"(L)",IF($U10=$H$17,"(L)","")))))))))))))) | AE10: =CONCATENATE(IF($U10=$L$5,$K$5,IF($U10=$L$6,$K$6,IF($U10=$L$7,$K$7,IF($U10=$L$8,$K$8,IF($U10=$L$9,$K$9,IF($U10=$L$10,$K$10,IF($U10=$L$11,$K$11,IF($U10=$L$12,$K$12,IF($U10=$L$13,$K$13,IF($U10=$L$14,$K$14,IF($U10=$L$15,$K$15,IF($U10=$L$16,$K$16,IF($U10=$L$17,$K$17,"")))))))))))))&" "&IF($U10=$L$5,"(A)",IF($U10=$L$6,"(B)",IF($U10=$L$7,"(C)",IF($U10=$L$8,"(D)",IF($U10=$L$9,"(E)",IF($U10=$L$10,"(F)",IF($U10=$L$11,"(G)",IF($U10=$L$12,"(H)",IF($U10=$L$13,"(I)",IF($U10=$L$14,"(J)",IF($U10=$L$15,"(K)",IF($U10=$L$16,"(L)",IF($U10=$L$17,"(L)","")))))))))))))) | AF10: =CONCATENATE(IF($U10=$N$5,$M$5,IF($U10=$N$6,$M$6,IF($U10=$N$7,$M$7,IF($U10=$N$8,$M$8,IF($U10=$N$9,$M$9,IF($U10=$N$10,$M$10,IF($U10=$N$11,$M$11,IF($U10=$N$12,$M$12,IF($U10=$N$13,$M$13,IF($U10=$N$14,$M$14,IF($U10=$N$15,$M$15,IF($U10=$N$16,$M$16,IF($U10=$N$17,$M$17,"")))))))))))))&" "&(IF($U10=$N$5,"(A)",IF($U10=$N$6,"(B)",IF($U10=$N$7,"(C)",IF($U10=$N$8,"(D)",IF($U10=$N$9,"(E)",IF($U10=$N$10,"(F)",IF($U10=$N$11,"(G)",IF($U10=$N$12,"(H)",IF($U10=$N$13,"(I)",IF($U10=$N$14,"(J)",IF($U10=$N$15,"(K)",IF($U10=$N$16,"(L)",IF($U10=$N$17,"(L)",""))))))))))))))) | AG10: =CONCATENATE(IF($U10=$F$21,$E$21,IF($U10=$F$22,$E$22,IF($U10=$F$23,$E$23,IF($U10=$F$24,$E$24,IF($U10=$F$25,$E$25,IF($U10=$F$26,$E$26,IF($U10=$F$27,$E$27,IF($U10=$F$28,$E$28,IF($U10=$F$29,$E$29,IF($U10=$F$30,$E$30,IF($U10=$F$31,$E$31,IF($U10=$F$32,$E$32,IF($U10=$F$33,$E$33,IF($U10=$F$34,$E$34,"")))))))))))))&" "&(IF($U10=$F$21,"(A)",IF($U10=$F$22,"(B)",IF($U10=$F$23,"(C)",IF($U10=$F$24,"(D)",IF($U10=$F$25,"(E)",IF($U10=$F$26,"(F)",IF($U10=$F$27,"(G)",IF($U10=$F$28,"(H)",IF($U10=$F$29,"(I)",IF($U10=$F$30,"(J)",IF($U10=$D$63,"(K)",IF($U10=$F$32,"(L)",IF($U10=$F$33,"(M)",IF($U10=$F$34,"(N)",""))))))))))))))))) | AH10: =CONCATENATE(IF($U10=$H$21,$G$21,IF($U10=$H$22,$G$22,IF($U10=$H$23,$G$23,IF($U10=$H$24,$G$24,IF($U10=$H$25,$G$25,IF($U10=$H$26,$G$26,IF($U10=$H$27,$G$27,IF($U10=$H$28,$G$28,IF($U10=$H$29,$G$29,IF($U10=$H$30,$G$30,IF($U10=$H$31,$G$31,IF($U10=$H$32,$G$32,IF($U10=$H$33,$G$33,IF($U10=$H$34,$G$34,""))))))))))))))&" "&(IF($U10=$H$21,"(A)",IF($U10=$H$22,"(B)",IF($U10=$H$23,"(C)",IF($U10=$H$24,"(D)",IF($U10=$H$25,"(E)",IF($U10=$H$26,"(F)",IF($U10=$H$27,"(G)",IF($U10=$H$28,"(H)",IF($U10=$H$29,"(I)",IF($U10=$H$30,"(J)",IF($U10=$H$31,"(K)",IF($U10=$H$32,"(L)",IF($U10=$H$33,"(M)",IF($U10=$H$34,"(N)","")))))))))))))))) | AI10: =CONCATENATE(IF($U10=$L$21,$K$21,IF($U10=$L$22,$K$22,IF($U10=$L$23,$K$23,IF($U10=$L$24,$K$24,IF($U10=$L$25,$K$25,IF($U10=$L$26,$K$26,IF($U10=$L$27,$K$27,IF($U10=$L$28,$K$28,IF($U10=$L$29,$K$29,IF($U10=$L$30,$K$30,IF($U10=$L$31,$K$31,IF($U10=$L$32,$K$32,IF($U10=$L$33,$K$33,IF($U10=$L$34,$K$34,""))))))))))))))&" "&IF($U10=$L$21,"(A)",IF($U10=$L$22,"(B)",IF($U10=$L$23,"(C)",IF($U10=$L$24,"(D)",IF($U10=$L$25,"(E)",IF($U10=$L$26,"(F)",IF($U10=$L$27,"(G)",IF($U10=$L$28,"(H)",IF($U10=$L$29,"(I)",IF($U10=$L$30,"(J)",IF($U10=$L$31,"(K)",IF($U10=$L$32,"(L)",IF($U10=$L$33,"(M)",IF($U10=$L$34,"(N)",""))))))))))))))) | AJ10: =CONCATENATE(IF($U10=$N$21,$M$21,IF($U10=$N$22,$M$22,IF($U10=$N$23,$M$23,IF($U10=$N$24,$M$24,IF($U10=$N$25,$M$25,IF($U10=$N$26,$M$26,IF($U10=$N$27,$M$27,IF($U10=$N$28,$M$28,IF($U10=$N$29,$M$29,IF($U10=$N$30,$M$30,IF($U10=$N$31,$M$31,IF($U10=$N$32,$M$32,IF($U10=$N$33,$M$33,IF($U10=$N$34,$M$34,""))))))))))))))&" "&(IF($U10=$N$21,"(A)",IF($U10=$N$22,"(B)",IF($U10=$N$23,"(C)",IF($U10=$N$24,"(D)",IF($U10=$N$25,"(E)",IF($U10=$N$26,"(F)",IF($U10=$N$27,"(G)",IF($U10=$N$28,"(H)",IF($U10=$N$29,"(I)",IF($U10=$N$30,"(J)",IF($U10=$N$31,"(K)",IF($U10=$N$32,"(L)",IF($U10=$N$33,"(M)",IF($U10=$N$34,"(N)","")))))))))))))))) | AK10: =CONCATENATE(IF($U10=$F$37,$E$37,IF($U10=$F$38,$E$38,IF($U10=$F$39,$E$39,IF($U10=$F$40,$E$40,IF($U10=$F$41,$E$41,IF($U10=$F$42,$E$42,IF($U10=$F$43,$E$43,IF($U10=$F$44,$E$44,IF($U10=$F$45,$E$45,IF($U10=$F$46,$E$46,IF($U10=$F$47,$E$47,IF($U10=$F$48,$E$48,IF($U10=$F$49,$E$49,IF($U10=$F$50,$E$50,IF($U10=$F$51,$E$51,""))))))))))))))&" "&IF($U10=$F$38,"(A)",IF($U10=$F$39,"(B)",IF($U10=$F$40,"(C)",IF($U10=$F$41,"(D)",IF($U10=$F$42,"(E)",IF($U10=$F$43,"(F)",IF($U10=$F$44,"(G)",IF($U10=$F$45,"(H)",IF($U10=$F$46,"(I)",IF($U10=$F$47,"(J)",IF($U10=$F$48,"(K)",IF($U10=$F$49,"(L)",IF($U10=$F$50,"(M)",IF($U10=$F$51,"(N)","")))))))))))))))) -> BT (K) | AL10: =CONCATENATE(IF($U10=$H$37,$G$37,IF($U10=$H$38,$G$38,IF($U10=$H$39,$G$39,IF($U10=$H$40,$G$40,IF($U10=$H$41,$G$41,IF($U10=$H$42,$G$42,IF($U10=$H$43,$G$43,IF($U10=$H$44,$G$44,IF($U10=$H$45,$G$45,IF($U10=$H$46,$G$46,IF($U10=$H$47,$G$47,IF($U10=$H$48,$G$48,IF($U10=$H$49,$G$49,IF($U10=$H$50,$G$50,IF($U10=$H$51,$G$51,"")))))))))))))))&" "&IF($U10=$H$38,"(A)",IF($U10=$H$39,"(B)",IF($U10=$H$40,"(C)",IF($U10=$H$41,"(D)",IF($U10=$H$42,"(E)",IF($U10=$H$43,"(F)",IF($U10=$H$44,"(G)",IF($U10=$H$45,"(H)",IF($U10=$H$46,"(I)",IF($U10=$H$47,"(J)",IF($U10=$H$48,"(K)",IF($U10=$H$49,"(L)",IF($U10=$H$50,"(M)",IF($U10=$H$51,"(N)",""))))))))))))))) | AM10: =CONCATENATE(IF($U10=$L$37,$K$37,IF($U10=$L$38,$K$38,IF($U10=$L$39,$K$39,IF($U10=$L$40,$K$40,IF($U10=$L$41,$K$41,IF($U10=$L$42,$K$42,IF($U10=$L$43,$K$43,IF($U10=$L$44,$K$44,IF($U10=$L$45,$K$45,IF($U10=$L$46,$K$46,IF($U10=$L$47,$K$47,IF($U10=$L$48,$K$48,IF($U10=$L$49,$K$49,IF($U10=$L$50,$K$50,IF($U10=$L$51,$K$51,"")))))))))))))))&" "&IF($U10=$L$38,"(A)",IF($U10=$L$39,"(B)",IF($U10=$L$40,"(C)",IF($U10=$L$41,"(D)",IF($U10=$L$42,"(E)",IF($U10=$L$43,"(F)",IF($U10=$L$44,"(G)",IF($U10=$L$45,"(H)",IF($U10=$L$46,"(I)",IF($U10=$L$47,"(J)",IF($U10=$L$48,"(K)",IF($U10=$L$49,"(L)",IF($U10=$L$50,"(M)",IF($U10=$L$51,"(N)",""))))))))))))))) -> BT (A) | AN10: =CONCATENATE(IF($U10=$N$37,$M$37,IF($U10=$N$38,$M$38,IF($U10=$N$39,$M$39,IF($U10=$N$40,$M$40,IF($U10=$N$41,$M$41,IF($U10=$N$42,$M$42,IF($U10=$N$43,$M$43,IF($U10=$N$44,$M$44,IF($U10=$N$45,$M$45,IF($U10=$N$46,$M$46,IF($U10=$N$47,$M$47,IF($U10=$N$48,$M$48,IF($U10=$N$49,$M$49,IF($U10=$N$50,$M$50,IF($U10=$N$51,$M$51,"")))))))))))))))&" "&IF($U10=$N$38,"(A)",IF($U10=$N$39,"(B)",IF($U10=$N$40,"(C)",IF($U10=$N$41,"(D)",IF($U10=$N$42,"(E)",IF($U10=$N$43,"(F)",IF($U10=$N$44,"(G)",IF($U10=$N$45,"(H)",IF($U10=$N$46,"(I)",IF($U10=$N$47,"(J)",IF($U10=$N$48,"(K)",IF($U10=$N$49,"(L)",IF($U10=$N$50,"(M)",IF($U10=$N$51,"(N)","")))))))))))))))
